Workbook

Sheet Revision
A1: Vendor | B1: Site
A2: Magsound | B2: Ningbo
A3: Project | B3: Build
A4: B747 BUD | B4: Ramp
A5: APN | B5: Description
A6: 160-05811-B(Mirror 160-05815-B) 160-05812-B(Mirror 160-05816-B) 160-05813-B(Mirror 160-05817-B) 160-05814-B(Mirror 160-05816-B) 806-55638-A(Mirror 806-55645-A) | B6: IQC
A7: 160-05811-B(Mirror 160-05815-B) 160-05812-B(Mirror 160-05816-B) 160-05813-B(Mirror 160-05817-B) 160-05814-B(Mirror 160-05816-B) | B7: Machining
A8: 160-05811-B(Mirror 160-05815-B) 160-05812-B(Mirror 160-05816-B) 160-05813-B(Mirror 160-05817-B) 160-05814-B(Mirror 160-05816-B) | B8: Surface Treatment
A9: 613-35102-B(Mirror 613-35106-B) | B9: Assembing
A10: 613-35102-B(Mirror 613-35106-B) | B10: OQC
A11: 160-05811-B(Mirror 160-05815-B) 160-05812-B(Mirror 160-05816-B) 160-05813-B(Mirror 160-05817-B) 160-05814-B(Mirror 160-05816-B) 806-55638-A(Mirror 806-55645-A) 613-35102-B(Mirror 613-35106-B) | B11: Rel
A13: Revision | B13: Date | C13: Revision for | I13: Revision Description | J13: Editor | K13: Approver
C14: IQC | D14: Machining | E14: Surface Treatment | F14: Assembing | G14: OQC | H14: Rel
A15: 1 | B15: 45712 | C15: Yes | D15: Yes | E15: Yes | F15: Yes | G15: Yes | H15: Yes | I15: Initial release for EVT Build | J15: Leo Lai | K15: Ray Fu
A16: 2 | B16: 45777 | C16: Yes | D16: Yes | E16: Yes | F16: Yes | G16: Yes | H16: Yes | I16: Initial release for DVT Build | J16: Leo Lai | K16: Liao wei
A17: 3 | B17: 45826 | C17: Yes | D17: Yes | E17: Yes | F17: Yes | G17: Yes | H17: Yes | I17: Initial release for Ramp Build | J17: Leo Lai | K17: Liao wei
A18: 4 | B18: 45834 | C18: Yes | D18: Yes | E18: Yes | F18: Yes | G18: Yes | H18: Yes | I18: Updated SF and AF spec | J18: Leo Lai | K18: Liao wei
A19: 5 | B19: 45854 | C19: Yes | D19: Yes | E19: Yes | F19: Yes | G19: Yes | H19: Yes | I19: Release for Ver. A | J19: Leo Lai | K19: Liao wei
A20: 6 | B20: 45917 | C20: Yes | D20: Yes | E20: Yes | F20: Yes | G20: Yes | H20: Yes | I20: Add HRE-FREE Specification To Materia | J20: Leo Lai | K20: Liao wei

Sheet IQC
A1: Project | B1: Build
A2: =IF(Revision!A4="","",Revision!A4) -> B747 BUD | B2: =IF(Revision!B4="","",Revision!B4) -> Ramp
A3: APN | B3: Description
A4: =Revision!A6 -> 160-05811-B(Mirror 160-05815-B) 160-05812-B(Mirror 160-05816-B) 160-05813-B(Mirror 160-05817-B) 160-05814-B(Mirror 160-05816-B) 806-55638-A(Mirror 806-55645-A) | B4: =Revision!B6 -> IQC
A6: Part Name | B6: APN | C6: Revision | D6: Category Dim, Cos, Function, ORT, Rel | E6: Description Detailed inspection items | F6: Control Plan Refer "IQC Reaction Plan"
F7: Inspection Equipment | G7: Sampling Plan | H7: Acceptance Criteria
A8: MAGNET,BUD RET,R1,B747 （MAGNET,BUD RET,L1,B747） | B8: 160-05811-B (Mirror 160-05815-B) N54M , HRE-Free | C8: 6 | D8: Function | E8: 剩磁 Br 14.5-14.9 kGs | F8: 磁性能测试仪AMT-4 Magnetic permanent tester | G8: 3pcs/Furnace炉 | H8: 0收1退(Ac=0)
C9: 6 | D9: Function | E9: 最大磁能积 BH max 50-55 MGOe | F9: 磁性能测试仪AMT-4 Magnetic permanent tester | G9: 3pcs/Furnace炉 | H9: 0收1退(Ac=0)
C10: 6 | D10: Function | E10: 内禀矫顽力 Hcj >14 kOe Min | F10: 磁性能测试仪AMT-4 Magnetic permanent tester | G10: 3pcs/Furnace炉 | H10: 0收1退(Ac=0)
C11: 6 | D11: ORT | E11: 硬度 Hardness HV 600±100 | F11: 硬度计 Hardmeter HVS-1000 | G11: 3pcs/Furnace炉 | H11: 0收1退(Ac=0)
C12: 6 | D12: ORT | E12: 密度 7.55~7.65 g/cm3 | F12: 密度 Drainage tester | G12: 3pcs/Furnace炉 | H12: 0收1退(Ac=0)
A13: MAGNET,BUD RET,R2,B747 （MAGNET,BUD RET,L2,B747） | B13: 160-05812-B (Mirror 160-05816-B) N54M , HRE-Free | C13: 6 | D13: Function | E13: 剩磁 Br 14.5-14.9 kGs | F13: 磁性能测试仪AMT-4 Magnetic permanent tester | G13: 3pcs/Furnace炉 | H13: 0收1退(Ac=0)
C14: 6 | D14: Function | E14: 最大磁能积 BH max 50-55 MGOe | F14: 磁性能测试仪AMT-4 Magnetic permanent tester | G14: 3pcs/Furnace炉 | H14: 0收1退(Ac=0)
C15: 6 | D15: Function | E15: 内禀矫顽力 Hcj >14 kOe Min | F15: 磁性能测试仪AMT-4 Magnetic permanent tester | G15: 3pcs/Furnace炉 | H15: 0收1退(Ac=0)
C16: 6 | D16: ORT | E16: 硬度 Hardness HV 600±100 | F16: 硬度计 Hardmeter HVS-1000 | G16: 3pcs/Furnace炉 | H16: 0收1退(Ac=0)
C17: 6 | D17: ORT | E17: 密度 7.55~7.65 g/cm3 | F17: 密度 Drainage tester | G17: 3pcs/Furnace炉 | H17: 0收1退(Ac=0)
A18: MAGNET,BUD RET,R3,B747 （MAGNET,BUD RET,L3,B747） | B18: 160-05813-B (Mirror 160-05817-B) N54M , HRE-Free | C18: 6 | D18: Function | E18: 剩磁 Br 14.5-14.9 kGs | F18: 磁性能测试仪AMT-4 Magnetic permanent tester | G18: 3pcs/Furnace炉 | H18: 0收1退(Ac=0)
C19: 6 | D19: Function | E19: 最大磁能积 BH max 50-55 MGOe | F19: 磁性能测试仪AMT-4 Magnetic permanent tester | G19: 3pcs/Furnace炉 | H19: 0收1退(Ac=0)
C20: 6 | D20: Function | E20: 内禀矫顽力 Hcj >14 kOe Min | F20: 磁性能测试仪AMT-4 Magnetic permanent tester | G20: 3pcs/Furnace炉 | H20: 0收1退(Ac=0)
C21: 6 | D21: ORT | E21: 硬度 Hardness HV 600±100 | F21: 硬度计 Hardmeter HVS-1000 | G21: 3pcs/Furnace炉 | H21: 0收1退(Ac=0)
C22: 6 | D22: ORT | E22: 密度 7.55~7.65 g/cm3 | F22: 密度 Drainage tester | G22: 3pcs/Furnace炉 | H22: 0收1退(Ac=0)
A23: MAGNET,BUD RET,R4,B747 （MAGNET,BUD RET,L4,B747） | B23: 160-05814-B (Mirror 160-05818-B) N54M , HRE-Free | C23: 6 | D23: Function | E23: 剩磁 Br 14.5-14.9 kGs | F23: 磁性能测试仪AMT-4 Magnetic permanent tester | G23: 3pcs/Furnace炉 | H23: 0收1退(Ac=0)
C24: 6 | D24: Function | E24: 最大磁能积 BH max 50-55 MGOe | F24: 磁性能测试仪AMT-4 Magnetic permanent tester | G24: 3pcs/Furnace炉 | H24: 0收1退(Ac=0)
C25: 6 | D25: Function | E25: 内禀矫顽力 Hcj >14 kOe Min | F25: 磁性能测试仪AMT-4 Magnetic permanent tester | G25: 3pcs/Furnace炉 | H25: 0收1退(Ac=0)
C26: 6 | D26: ORT | E26: 硬度 Hardness HV 600±100 | F26: 硬度计 Hardmeter HVS-1000 | G26: 3pcs/Furnace炉 | H26: 0收1退(Ac=0)
C27: 6 | D27: ORT | E27: 密度 7.55~7.65 g/cm3 | F27: 密度 Drainage tester | G27: 3pcs/Furnace炉 | H27: 0收1退(Ac=0)
A28: BACKING SHUNT,BUD RET,R,B747 （BACKING SHUNT,BUD RET,L,B747） | B28: 806-55638-A (Mirror 806-55645-A) | C28: 6 | D28: Dim | E28: Hardness Data collect Raw materials | F28: Hardness tester Supplier testing | G28: 3pcs/Lot | H28: 0收1退(Ac=0)
C29: 6 | D29: Dim | E29: Weight Data collect | F29: Electronic balance | G29: 32pcs/Lot | H29: 0收1退(Ac=0)
C30: 6 | D30: Dim | E30: FAI 1/SPC A 4.07±0.10mm | F30: Keyence | G30: 32pcs/Lot | H30: CPK≥1.33
C31: 6 | D31: Dim | E31: FAI 2/SPC B 9.07± 0.10mm | F31: Keyence | G31: 32pcs/Lot | H31: CPK≥1.33
C32: 6 | D32: Dim | E32: FAI 3/SPC C 2.07± 0.10mm | F32: Keyence | G32: 32pcs/Lot | H32: CPK≥1.33
C33: 6 | D33: Dim | E33: FAI 4/SPC D 0.1 MAX | F33: Keyence | G33: 32pcs/Lot | H33: CPK≥1.33
C34: 6 | D34: Dim | E34: FAI 5/SPC E 0.20±0.10mm | F34: MIC | G34: 32pcs/Lot | H34: CPK≥1.33
C35: 6 | D35: Dim | E35: Gloss 80~200Gu（Internal control） | F35: 光泽度计 Gloss Meter | G35: 9pcs/Lot | H35: No Alert(65%)
C36: 6 | D36: ORT | E36: ≥34（Internal control） | F36: 达因笔测试 Dyne test | G36: 9pcs/Lot | H36: 0收1退(Ac=0)
C37: 6 | D37: Cos | E37: 069-1770.Class C | F37: Visual Inspection | G37: GB2828 AQL 0.4 level 2 | H37: GB2828 AQL 0.4 level 2

Sheet Machining
B1: Project | C1: Build
B2: =IF(Revision!A4="","",Revision!A4) -> B747 BUD | C2: =IF(Revision!B4="","",Revision!B4) -> Ramp
B3: APN | C3: Description
B4: =Revision!A7 -> 160-05811-B(Mirror 160-05815-B) 160-05812-B(Mirror 160-05816-B) 160-05813-B(Mirror 160-05817-B) 160-05814-B(Mirror 160-05816-B) | C4: =Revision!B7 -> Machining
A6: APN | B6: Station Station No. with Description | C6: Category Dim, Cos, Function, ORT | D6: Apple DWG Apple official drawing for reference, DO NOT release for online control | G6: Internal DWG Vendor internal drawing been used for by station inspections | K6: FAI Control Plan Refer "Online Quality Control Reaction Plan" | M6: IPQC Control Plan Refer "Online Quality Control Reaction Plan"
D7: SPC No. | E7: FAI No. | F7: Spec | G7: Dim No. | H7: Spec | I7: Description | J7: CTQ Category | K7: FAI Spec | L7: Inspection Equipment | M7: IPQC Spec | N7: Inspection Equipment | O7: Inspection Frequency
A8: 160-05811-B (Mirror 160-05815-B) | B8: 1道线锯 1st Wire Saw | C8: Dim | D8: / | E8: / | F8: / | G8: / | H8: 6.29±0.05 mm | I8: 长 Length | J8: Not CTQ | K8: 6.29±0.04 mm | L8: MIC | M8: 6.29±0.04 mm | N8: MIC | O8: 5pcs/2h
B9: 1道双面磨 1st Double Side Grinding | C9: Dim | D9: / | E9: / | F9: / | G9: / | H9: 6.19±0.03 mm | I9: 长 Length | J9: Not CTQ | K9: 6.19±0.02 mm | L9: MIC | M9: 6.19±0.02 mm | N9: MIC | O9: 5pcs/2h
B10: 2道线锯 2nd Wire Saw | C10: Dim | D10: / | E10: / | F10: / | G10: / | H10: 4.20±0.05 mm | I10: 宽 Width | J10: Not CTQ | K10: 4.20±0.04 mm | L10: MIC | M10: 4.20±0.04 mm | N10: MIC | O10: 5pcs/2h
B11: 2道双面磨 2nd Double Side Grinding | C11: Dim | D11: / | E11: / | F11: / | G11: / | H11: 4.10±0.03 mm | I11: 宽 Width | J11: Not CTQ | K11: 4.10±0.02 mm | L11: MIC | M11: 4.10±0.02 mm | N11: MIC | O11: 5pcs/2h
B12: 1道轮廓磨 1st Profile Grinding | C12: Dim | D12: / | E12: / | F12: / | G12: / | H12: 2.59±0.03 mm | I12: 距离 Distance | J12: Not CTQ | K12: 2.59±0.02 mm | L12: OMM | M12: 2.59±0.02 mm | N12: OMM | O12: 5pcs/2h
C13: Dim | D13: / | E13: / | F13: / | G13: / | H13: 0.86±0.03 mm | I13: 距离 Distance | J13: Not CTQ | K13: 0.86±0.02 mm | L13: OMM | M13: 0.86±0.02 mm | N13: OMM | O13: 5pcs/2h
C14: Dim | D14: / | E14: / | F14: / | G14: / | H14: 72.70°±0.4° | I14: 角度 Angle | J14: Not CTQ | K14: 72.70°±0.3° | L14: OMM | M14: 72.70°±0.3° | N14: OMM | O14: 5pcs/2h
B15: 3道线锯 3rd Wire Saw | C15: Dim | D15: / | E15: / | F15: / | G15: / | H15: 2.81±0.05 mm | I15: 厚度 Thickness | J15: Not CTQ | K15: 2.81±0.04 mm | L15: MIC | M15: 2.81±0.04 mm | N15: MIC | O15: 5pcs/2h
B16: 3道双面磨 3rd Double Side Grinding | C16: Dim | D16: / | E16: / | F16: / | G16: / | H16: 2.71±0.03 mm | I16: 厚度 Thickness | J16: Not CTQ | K16: 2.71±0.02 mm | L16: MIC | M16: 2.71±0.02 mm | N16: MIC | O16: 5pcs/2h
B17: 2道轮廓磨 2nd Profile Grinding | C17: Dim | D17: / | E17: / | F17: / | G17: / | H17: 0.08 max | I17: 轮廓度 Profile | J17: Not CTQ | K17: 0.06 max | L17: CMM | M17: 0.06 max | N17: CMM | O17: 5pcs/2h
A18: 160-05812-B (Mirror 160-05816-B) | B18: 1道线锯 1st Wire Saw | C18: Dim | D18: / | E18: / | F18: / | G18: / | H18: 5.57 ±0.05 mm | I18: 长 Length | J18: Not CTQ | K18: 5.57 ±0.04 mm | L18: MIC | M18: 5.57 ±0.04 mm | N18: MIC | O18: 5pcs/2h
B19: 1道双面磨 1st Double Side Grinding | C19: Dim | D19: / | E19: / | F19: / | G19: / | H19: 5.47±0.03 mm | I19: 长 Length | J19: Not CTQ | K19: 5.47±0.02 mm | L19: MIC | M19: 5.47±0.02 mm | N19: MIC | O19: 5pcs/2h
B20: 2道线锯 2nd Wire Saw | C20: Dim | D20: / | E20: / | F20: / | G20: / | H20: 4.14±0.05 mm | I20: 宽 Width | J20: Not CTQ | K20: 4.14±0.04 mm | L20: MIC | M20: 4.14±0.04 mm | N20: MIC | O20: 5pcs/2h
B21: 2道双面磨 2nd Double Side Grinding | C21: Dim | D21: / | E21: / | F21: / | G21: / | H21: 4.04± 0.03 mm | I21: 宽 Width | J21: Not CTQ | K21: 4.04± 0.02 mm | L21: MIC | M21: 4.04± 0.02 mm | N21: MIC | O21: 5pcs/2h
B22: 1道轮廓磨 1st Profile Grinding | C22: Dim | D22: / | E22: / | F22: / | G22: / | H22: 2.59±0.03 mm | I22: 距离 Distance | J22: Not CTQ | K22: 2.59±0.02 mm | L22: OMM | M22: 2.59±0.02 mm | N22: OMM | O22: 5pcs/2h
C23: Dim | H23: 0.80±0.03 mm | I23: 距离 Distance | J23: Not CTQ | K23: 0.80±0.02 mm | L23: OMM | M23: 0.80±0.02 mm | N23: OMM | O23: 5pcs/2h
C24: Dim | D24: / | E24: / | F24: / | G24: / | H24: 72.70°±0.4° | I24: 角度 Angle | J24: Not CTQ | K24: 72.70°±0.3° | L24: OMM | M24: 72.70°±0.3° | N24: OMM | O24: 5pcs/2h
B25: 3道线锯 3rd Wire Saw | C25: Dim | D25: / | E25: / | F25: / | G25: / | H25: 2.67±0.05 mm | I25: 厚度 Thickness | J25: Not CTQ | K25: 2.67±0.04 mm | L25: MIC | M25: 2.67±0.04 mm | N25: MIC | O25: 5pcs/2h
B26: 3道双面磨 3rd Double Side Grinding | C26: Dim | D26: / | E26: / | F26: / | G26: / | H26: 2.57±0.03 mm | I26: 厚度 Thickness | J26: Not CTQ | K26: 2.57±0.02 mm | L26: MIC | M26: 2.57±0.02 mm | N26: MIC | O26: 5pcs/2h
B27: 2道轮廓磨 2nd Profile Grinding | C27: Dim | D27: / | E27: / | F27: / | G27: / | H27: 0.08 max | I27: 轮廓度 1 Profile 1 | J27: Not CTQ | K27: 0.06 max | L27: CMM | M27: 0.06 max | N27: CMM | O27: 5pcs/2h
C28: Dim | D28: / | E28: / | F28: / | G28: / | H28: 0.08 max | I28: 轮廓度 2 Profile 2 | J28: Not CTQ | K28: 0.06 max | L28: CMM | M28: 0.06 max | N28: CMM | O28: 5pcs/2h
A29: 160-05813-B (Mirror 160-05817-B) | B29: 1道线锯 1st Wire Saw | C29: Dim | D29: / | E29: / | F29: / | G29: / | H29: 4.28 ±0.05 mm | I29: 长 Length | J29: Not CTQ | K29: 4.28 ±0.04 mm | L29: MIC | M29: 4.28 ±0.04 mm | N29: MIC | O29: 5pcs/2h
B30: 1道双面磨 1st Double Side Grinding | C30: Dim | D30: / | E30: / | F30: / | G30: / | H30: 4.18 ±0.03 mm | I30: 长 Length | J30: Not CTQ | K30: 4.18 ±0.02 mm | L30: MIC | M30: 4.18 ±0.02 mm | N30: MIC | O30: 5pcs/2h
B31: 2道线锯 2nd Wire Saw | C31: Dim | D31: / | E31: / | F31: / | G31: / | H31: 3.90 ±0.05 mm | I31: 宽 Width | J31: Not CTQ | K31: 3.90 ±0.04 mm | L31: MIC | M31: 3.90 ±0.04 mm | N31: MIC | O31: 5pcs/2h
B32: 2道双面磨 2nd Double Side Grinding | C32: Dim | D32: / | E32: / | F32: / | G32: / | H32: 3.80± 0.03 mm | I32: 宽 Width | J32: Not CTQ | K32: 3.80± 0.02 mm | L32: MIC | M32: 3.80± 0.02 mm | N32: MIC | O32: 5pcs/2h
B33: 1道轮廓磨 1st Profile Grinding | C33: Dim | D33: / | E33: / | F33: / | G33: / | H33: 2.59±0.03 mm | I33: 距离 Distance | J33: Not CTQ | K33: 2.59±0.02 mm | L33: OMM | M33: 2.59±0.02 mm | N33: OMM | O33: 5pcs/2h
C34: Dim | D34: / | E34: / | F34: / | G34: / | H34: 0.56±0.03 mm | I34: 距离 Distance | J34: Not CTQ | K34: 0.56±0.02 mm | L34: OMM | M34: 0.56±0.02 mm | N34: OMM | O34: 5pcs/2h
C35: Dim | D35: / | E35: / | F35: / | G35: / | H35: 72.70°±0.4° | I35: 角度 Angle | J35: Not CTQ | K35: 72.70°±0.3° | L35: OMM | M35: 72.70°±0.3° | N35: OMM | O35: 5pcs/2h
B36: 3道线锯 3rd Wire Saw | C36: Dim | D36: / | E36: / | F36: / | G36: / | H36: 2.67±0.05 mm | I36: 厚度 Thickness | J36: Not CTQ | K36: 2.67±0.04 mm | L36: MIC | M36: 2.67±0.04 mm | N36: MIC | O36: 5pcs/2h
B37: 3道双面磨 3rd Double Side Grinding | C37: Dim | D37: / | E37: / | F37: / | G37: / | H37: 2.57±0.03 mm | I37: 厚度 Thickness | J37: Not CTQ | K37: 2.57±0.02 mm | L37: MIC | M37: 2.57±0.02 mm | N37: MIC | O37: 5pcs/2h
B38: 2道轮廓磨 2nd Profile Grinding | C38: Dim | D38: / | E38: / | F38: / | G38: / | H38: 0.08 max | I38: 轮廓度 Profile | J38: Not CTQ | K38: 0.06 max | L38: CMM | M38: 0.06 max | N38: CMM | O38: 5pcs/2h
A39: 160-05814-B (Mirror 160-05818-B) | B39: 1道线锯 1st Wire Saw | C39: Dim | D39: / | E39: / | F39: / | G39: / | H39: 4.36±0.05 mm | I39: 长 Length | J39: Not CTQ | K39: 4.36±0.04 mm | L39: MIC | M39: 4.36±0.04 mm | N39: MIC | O39: 5pcs/2h
B40: 1道双面磨 1st Double Side Grinding | C40: Dim | D40: / | E40: / | F40: / | G40: / | H40: 4.26±0.03 mm | I40: 长 Length | J40: Not CTQ | K40: 4.26±0.02 mm | L40: MIC | M40: 4.26±0.02 mm | N40: MIC | O40: 5pcs/2h
B41: 2道线锯 2nd Wire Saw | C41: Dim | D41: / | E41: / | F41: / | G41: / | H41: 3.90±0.05 mm | I41: 宽 Width | J41: Not CTQ | K41: 3.90±0.04mm | L41: MIC | M41: 3.90±0.04mm | N41: MIC | O41: 5pcs/2h
...

Sheet Surface Treatment
B1: Project | C1: Build
B2: =IF(Revision!A4="","",Revision!A4) -> B747 BUD | C2: =IF(Revision!B4="","",Revision!B4) -> Ramp
B3: APN | C3: Description
B4: =Revision!A8 -> 160-05811-B(Mirror 160-05815-B) 160-05812-B(Mirror 160-05816-B) 160-05813-B(Mirror 160-05817-B) 160-05814-B(Mirror 160-05816-B) | C4: =Revision!B8 -> Surface Treatment
A6: APN | B6: Station Station No. with Description | C6: Category Dim, Cos, Function, ORT | D6: Apple DWG Apple official drawing for reference, DO NOT release for online control | G6: Internal DWG Vendor internal drawing been used for by station inspections | K6: FAI Control Plan Refer "Online Quality Control Reaction Plan" | M6: IPQC Control Plan Refer "Online Quality Control Reaction Plan"
D7: SPC No. | E7: FAI No. | F7: Spec | G7: Dim No. | H7: Spec | I7: Description | J7: CTQ Category | K7: FAI Spec | L7: Inspection Equipment | M7: IPQC Spec | N7: Inspection Equipment | O7: Inspection Frequency
A8: 160-05811-B(Mirror 160-05815-B) 160-05812-B(Mirror 160-05816-B) 160-05813-B(Mirror 160-05817-B) 160-05814-B(Mirror 160-05816-B) | B8: 滚动研磨 Tumbling | C8: Cos | D8: / | E8: / | F8: / | G8: / | H8: ≤0.2mm | I8: 倒角度 Corner radius | J8: Not CTQ | K8: 0.1-0.2mm | L8: 投影仪 Profile Projector | M8: 0.1-0.2mm | N8: 投影仪 Profile Projector | O8: 5pcs/Barrel
A9: 160-05811-B(Mirror 160-05815-B) 160-05812-B(Mirror 160-05816-B) 160-05813-B(Mirror 160-05817-B) 160-05814-B(Mirror 160-05816-B) | B9: NiCuNi 电镀 NiCuNi Plating | C9: Dim | D9: / | E9: / | F9: Ni：2.0～5.0μm Cu：2.0～5.0μm Ni：3.0～9.0μm Total：7.0～19.0μm | G9: / | H9: Ni：2.0～5.0μm Cu：2.0～5.0μm Ni：3.0～9.0μm Total：7.0～19.0μm | I9: 单边镀层厚度 Single side plating thickness | J9: Not CTQ | K9: Ni：2.0～5.0μm Cu：2.0～5.0μm Ni：3.0～9.0μm Total：7.0～19.0μm | L9: X射线测厚仪 EDXRF Spectrometer | M9: Ni：2.0～5.0μm Cu：2.0～5.0μm Ni：3.0～9.0μm Total：7.0～19.0μm | N9: X射线测厚仪 EDXRF Spectrometer | O9: 9pcs/Barrel
C10: Dim | D10: / | E10: / | F10: / | G10: / | H10: 80-200 GU | I10: 光泽 Gloss | J10: Not CTQ | K10: 80-200 GU | L10: 光泽度计 Gloss Meter | M10: 80-200 GU | N10: 光泽度计 Gloss Meter | O10: 9pcs/Barrel
C11: Dim | D11: / | E11: / | F11: / | G11: / | H11: Data collect | I11: 色差 Color | J11: Not CTQ | K11: Data collect | L11: 色差计 Color Meter | M11: Data collect | N11: 色差计 Color Meter | O11: 3pcs/Barrel
C12: Dim | D12: / | E12: / | F12: / | G12: / | H12: Data collect | I12: 粗糙度 X/Y Roughness X/Y | J12: Not CTQ | K12: Data collect | L12: 粗糙度仪 Roughness Meter | M12: Data collect | N12: 粗糙度仪 Roughness Meter | O12: 9pcs/Barrel
C13: ORT | D13: / | E13: / | F13: / | G13: / | H13: 4B | I13: 百格测试 Cross hatch testing | J13: Not CTQ | K13: 4B | L13: 划格刀 Knife | M13: 4B | N13: 划格刀 Knife | O13: 9pcs/Barrel
C14: ORT | D14: / | E14: / | F14: / | G14: / | H14: ≥34 | I14: 达因笔测试 Dyne test | J14: Not CTQ | K14: ≥34 | L14: 达因笔 Dyne pen | M14: ≥34 | N14: 达因笔 Dyne pen | O14: 9pcs/Barrel
C15: Cos | D15: / | E15: / | F15: 069-1770.Class C | G15: / | H15: 069-1770.Class C | I15: 外观 Cosmetic | J15: Not CTQ | K15: 069-1770.Class C | L15: 目视 Visual | M15: 069-1770.Class C | N15: 目视 Visual | O15: GB2828 AQL 0.65 level 2
A16: 160-05811-B(Mirror 160-05815-B) | B16: IPQC检验 | C16: Dim | D16: A | E16: 1 | F16: 2.71±0.10 mm | G16: FAI 1/SPC A | H16: 2.71±0.08 mm | I16: 厚度 Thickness | J16: Not CTQ | K16: 2.71±0.08 mm | L16: MIC | M16: 2.71±0.08 mm | N16: MIC | O16: 32pcs/Lot
C17: Dim | D17: B | E17: 2 | F17: 6.19± 0.10 mm | G17: FAI 2/SPC B | H17: 6.19± 0.08 mm | I17: 长 Length | J17: Not CTQ | K17: 6.19± 0.08 mm | L17: Keyence | M17: 6.19± 0.08 mm | N17: Keyence | O17: 32pcs/Lot
C18: Dim | D18: C | E18: 3 | F18: 4.10± 0.10 mm | G18: FAI 3/SPC C | H18: 4.10± 0.10 mm | I18: 宽 Width | J18: Not CTQ | K18: 4.10± 0.10 mm | L18: Keyence | M18: 4.10± 0.10 mm | N18: Keyence | O18: 32pcs/Lot
C19: Dim | D19: D | E19: 4 | G19: FAI 4/SPC D | H19: 0.08max | I19: 面轮廓 Surface profile | J19: Not CTQ | K19: 0.08max | L19: CMM | M19: 0.08max | N19: CMM | O19: 32pcs/Lot
C20: Dim | D20: E | E20: 5 | F20: 2.59± 0.10 mm | G20: FAI 5/SPC E | H20: 2.59± 0.08 mm | I20: 距离 distance | J20: Not CTQ | K20: 2.59± 0.08 mm | L20: Keyence | M20: 2.59± 0.08 mm | N20: Keyence | O20: 32pcs/Lot
C21: Dim | D21: F | E21: 6 | F21: 0.86± 0.10 mm | G21: FAI 6/SPC F | H21: 0.86± 0.08 mm | I21: 距离 distance | J21: Not CTQ | K21: 0.86± 0.08 mm | L21: Keyence | M21: 0.86± 0.08 mm | N21: Keyence | O21: 32pcs/Lot
C22: Dim | D22: G | E22: 7 | F22: 2.56± 0.10 mm | G22: FAI 7/SPC G | H22: 2.56± 0.08 mm | I22: 距离 distance | J22: Not CTQ | K22: 2.56± 0.08 mm | L22: Keyence | M22: 2.56± 0.08 mm | N22: Keyence | O22: 32pcs/Lot
C23: Dim | D23: H | E23: 8 | G23: FAI 8/SPC H | H23: 0.08max | I23: 面轮廓 Surface profile | J23: Not CTQ | K23: 0.08max | L23: CMM | M23: 0.08max | N23: CMM | O23: 32pcs/Lot
C24: Dim | D24: / | E24: / | F24: / | G24: / | H24: 80-200 GU | I24: 光泽 Gloss | J24: Not CTQ | K24: 80-200 GU | L24: 光泽度计 Gloss Meter | M24: 80-200 GU | N24: 光泽度计 Gloss Meter | O24: 9pcs/Lot
C25: Dim | D25: / | E25: / | F25: / | G25: / | H25: Data collect | I25: 色差 Color | J25: Not CTQ | K25: Data collect | L25: 色差计 Color Meter | M25: Data collect | N25: 色差计 Color Meter | O25: 3pcs/Lot
C26: Dim | D26: / | E26: / | F26: / | G26: / | H26: Data collect | I26: 粗糙度 X/Y Roughness X/Y | J26: Not CTQ | K26: Data collect | L26: 粗糙度仪 Roughness Meter | M26: Data collect | N26: 粗糙度仪 Roughness Meter | O26: 9pcs/Lot
C27: Dim | D27: / | E27: / | F27: Top layer: Ni 2.0-5.0μm | G27: / | H27: Top layer: Ni 2.0-5.0μm | I27: Plating Thickness | J27: Not CTQ | K27: Top layer: Ni 2.0-5.0μm | L27: 切片+金相 Section+Optical Microscope | M27: Top layer: Ni 2.0-5.0μm | N27: 切片+金相 Section+Optical Microscope | O27: 9pcs/Lot
C28: Dim | D28: / | E28: / | F28: Mid layer: Cu 2.0-5.0μm | G28: / | H28: Mid layer: Cu 2.0-5.0μm | J28: Not CTQ | K28: Mid layer: Cu 2.0-5.0μm | M28: Mid layer: Cu 2.0-5.0μm | O28: 9pcs/Lot
C29: Dim | D29: / | E29: / | F29: Base layer: Ni 3.0-9.0μm | G29: / | H29: Base layer: Ni 3.0-9.0μm | J29: Not CTQ | K29: Base layer: Ni 3.0-9.0μm | M29: Base layer: Ni 3.0-9.0μm | O29: 9pcs/Lot
C30: Dim | D30: / | E30: / | F30: Single sided plating thickness 7.0-19.0μm | G30: / | H30: Single sided plating thickness 7.0-19.0μm | J30: Not CTQ | K30: Single sided plating thickness 7.0-19.0μm | M30: Single sided plating thickness 7.0-19.0μm | O30: 9pcs/Lot
C31: Function | D31: I | E31: 9 | F31: 8.002±0.40 μWb*cm | G31: FAI 9/SPC I | H31: 8.002±0.40 μWb*cm | I31: Magnetic Moment | J31: Not CTQ | K31: 8.002±0.32 μWb*cm | L31: Three-dimensional coil tester | M31: 8.002±0.32 μWb*cm | N31: Three-dimensional coil tester | O31: 32pcs/Lot
C32: Function | D32: J | E32: 10 | F32: 70.00±7° | G32: / | H32: 70.00°±5.0° | I32: Polarity Angle | J32: Not CTQ | K32: 70.00°±5.0° | L32: Three-dimensional coil tester | M32: 70.00°±5.0° | N32: Three-dimensional coil tester | O32: 32pcs/Lot
C33: ORT | D33: / | E33: / | F33: / | G33: / | H33: 4B | I33: 百格测试 Cross hatch testing | J33: Not CTQ | K33: 4B | L33: 划格刀 Knife | M33: 4B | N33: 划格刀 Knife | O33: 9pcs/Lot
C34: ORT | D34: / | E34: / | F34: / | G34: / | H34: ≥34 | I34: 达因笔测试 Dyne test | J34: Not CTQ | K34: ≥34 | L34: 达因笔 Dyne pen | M34: ≥34 | N34: 达因笔 Dyne pen | O34: 9pcs/Lot
B35: AOI 100%检验 AOI 100%inspection | C35: Dim | D35: A | E35: 1 | F35: 2.71±0.10 mm | G35: FAI 1/SPC A | H35: 2.71±0.09 mm | I35: 厚度 Thickness | J35: Not CTQ | K35: 2.71±0.09 mm | L35: MIC | M35: 2.71±0.09 mm | N35: MIC | O35: 3pcs/4h
C36: Dim | D36: B | E36: 2 | F36: 6.19± 0.10 mm | G36: FAI 2/SPC B | H36: 6.19± 0.09 mm | I36: 长 Length | J36: Not CTQ | K36: 6.19± 0.09 mm | L36: Keyence | M36: 6.19± 0.09 mm | N36: Keyence | O36: 3pcs/4h
C37: Dim | D37: C | E37: 3 | F37: 4.10± 0.10 mm | G37: FAI 3/SPC C | H37: 4.10± 0.09 mm | I37: 宽 Width | J37: Not CTQ | K37: 4.10± 0.09 mm | L37: Keyence | M37: 4.10± 0.09 mm | N37: Keyence | O37: 3pcs/4h
C38: Dim | D38: E | E38: 5 | F38: 2.59± 0.10 mm | G38: FAI 5/SPC E | H38: 2.59± 0.09 mm | I38: 距离 distance | J38: Not CTQ | K38: 2.59± 0.09 mm | L38: Keyence | M38: 2.59± 0.09 mm | N38: Keyence | O38: 3pcs/4h
C39: Dim | D39: F | E39: 6 | F39: 0.86± 0.10 mm | G39: FAI 6/SPC F | H39: 0.86± 0.09 mm | I39: 距离 distance | J39: Not CTQ | K39: 0.86± 0.09 mm | L39: Keyence | M39: 0.86± 0.09 mm | N39: Keyence | O39: 3pcs/4h
C40: Dim | D40: G | E40: 7 | F40: 2.56± 0.10 mm | G40: FAI 7/SPC G | H40: 2.56± 0.09 mm | I40: 距离 distance | J40: Not CTQ | K40: 2.56± 0.09 mm | L40: Keyence | M40: 2.56± 0.09 mm | N40: Keyence | O40: 3pcs/4h
C41: Cos | D41: / | E41: / | F41: 069-1770.Class C | G41: / | H41: 069-1770.Class C | I41: 外观 Cosmetic | J41: Not CTQ | K41: 069-1770.Class C | L41: 目视 Visual | M41: 069-1770.Class C | N41: 目视 Visual | O41: 500pcs/4h
...

Sheet Assembing
A1: Project | B1: Build
A2: =IF(Revision!A4="","",Revision!A4) -> B747 BUD | B2: =IF(Revision!B4="","",Revision!B4) -> Ramp
A3: APN | B3: Description
A4: =Revision!A9 -> 613-35102-B(Mirror 613-35106-B) | B4: =Revision!B9 -> Assembing
A6: Station Station No. with Description | B6: Category Dim, Cos, Function, ORT | C6: Apple DWG Apple official drawing for reference, DO NOT release for online control | F6: Internal DWG Vendor internal drawing been used for by station inspections | J6: FAI Control Plan Refer "Online Quality Control Reaction Plan" | L6: IPQC Control Plan Refer "Online Quality Control Reaction Plan"
C7: SPC No. | D7: FAI No. | E7: Spec | F7: Dim No. | G7: Spec | H7: Description | I7: CTQ Category | J7: FAI Spec | K7: Inspection Equipment | L7: IPQC Spec | M7: Inspection Equipment | N7: Inspection Frequency
A8: Magnetization 160-05811-90(Mirror 160-05815-90) | B8: Function | C8: I | D8: 9 | E8: 8.002±0.40 μWb*cm | F8: FAI 9/SPC I | G8: 8.002±0.32 μWb*cm | H8: MM 磁矩 | I8: Critical to FATP | J8: 8.002±0.32 μWb*cm | K8: Three-dimensional coil tester | L8: 8.002±0.32 μWb*cm | M8: Three-dimensional coil tester | N8: 5pcs/4h
B9: Function | C9: J | D9: 10 | E9: 70.00±7° | F9: / | G9: 70.00°±5.0° | H9: Polarity Angle | I9: Not CTQ | J9: 70.00°±5.0° | K9: Three-dimensional coil tester | L9: 70.00°±5.0° | M9: Three-dimensional coil tester | N9: 5pcs/4h
B10: Function | C10: / | D10: / | E10: / | F10: / | G10: The outline of the image displayed on the magnetic film is clearly visible | H10: Magnetic film | I10: Critical to FATP | J10: The outline of the image displayed on the magnetic film is clearly visible | K10: 磁极片 Magnetic film | L10: The outline of the image displayed on the magnetic film is clearly visible | M10: 磁极片 Magnetic film | N10: NPI Production:100% inspection
B11: Function | C11: / | D11: / | E11: / | F11: / | G11: Polarity Check | H11: Polarity | I11: Critical to FATP | J11: Polarity Check | K11: 极性笔 Polar Pen | L11: Polarity Check | M11: 极性笔 Polar Pen | N11: NPI Production:100% inspection
A12: Magnetization 160-05812-90(Mirror 160-05816-90) | B12: Function | C12: J | D12: 10 | E12: 5.663 ±0.283 μWb*cm | F12: FAI 10/SPC J | G12: 5.663 ±0.226 μWb*cm | H12: MM 磁矩 | I12: Critical to FATP | J12: 5.663 ±0.226 μWb*cm | K12: Three-dimensional coil tester | L12: 5.663 ±0.226 μWb*cm | M12: Three-dimensional coil tester | N12: 5pcs/4h
B13: Function | C13: K | D13: 11 | E13: 30±7° | F13: / | G13: 30±5° | H13: Polarity Angle | I13: Not CTQ | J13: 30±5° | K13: Three-dimensional coil tester | L13: 30±5° | M13: Three-dimensional coil tester | N13: 5pcs/4h
B14: Function | C14: / | D14: / | E14: / | F14: / | G14: The outline of the image displayed on the magnetic film is clearly visible | H14: Magnetic film | I14: Critical to FATP | J14: The outline of the image displayed on the magnetic film is clearly visible | K14: 磁极片 Magnetic film | L14: The outline of the image displayed on the magnetic film is clearly visible | M14: 磁极片 Magnetic film | N14: NPI Production:100% inspection
B15: Function | C15: / | D15: / | E15: / | F15: / | G15: Polarity Check | H15: Polarity | I15: Critical to FATP | J15: Polarity Check | K15: 极性笔 Polar Pen | L15: Polarity Check | M15: 极性笔 Polar Pen | N15: NPI Production:100% inspection
A16: Magnetization 160-05813-90(Mirror 160-05817-90) | B16: Function | C16: I | D16: 9 | E16: 4.664 ±0.233 μWb*cm | F16: FAI 9/SPC I | G16: 4.664 ±0.233 μWb*cm | H16: MM 磁矩 | I16: Critical to FATP | J16: 4.664 ±0.186 μWb*cm | K16: Three-dimensional coil tester | L16: 4.664 ±0.186 μWb*cm | M16: Three-dimensional coil tester | N16: 5pcs/4h
B17: Function | C17: J | D17: 10 | E17: 10±7° | F17: / | G17: 10±5° | H17: Polarity Angle | I17: Not CTQ | J17: 10±5° | K17: Three-dimensional coil tester | L17: 10±5° | M17: Three-dimensional coil tester | N17: 5pcs/4h
B18: Function | C18: / | D18: / | E18: / | F18: / | G18: The outline of the image displayed on the magnetic film is clearly visible | H18: Magnetic film | I18: Critical to FATP | J18: The outline of the image displayed on the magnetic film is clearly visible | K18: 磁极片 Magnetic film | L18: The outline of the image displayed on the magnetic film is clearly visible | M18: 磁极片 Magnetic film | N18: NPI Production:100% inspection
B19: Function | C19: / | D19: / | E19: / | F19: / | G19: Polarity Check | H19: Polarity | I19: Critical to FATP | J19: Polarity Check | K19: 极性笔 Polar Pen | L19: Polarity Check | M19: 极性笔 Polar Pen | N19: NPI Production:100% inspection
A20: Magnetization 160-05814-90(Mirror 160-05818-90) | B20: Function | C20: J | D20: 10 | E20: 3.128 ±0.56 μWb*cm | F20: FAI 10/SPC J | G20: 3.128 ±0.124 μWb*cm | H20: MM 磁矩 | I20: Critical to FATP | J20: 3.128 ±0.124 μWb*cm | K20: Three-dimensional coil tester | L20: 3.128 ±0.124 μWb*cm | M20: Three-dimensional coil tester | N20: 5pcs/4h
B21: Function | C21: K | D21: 11 | E21: 40±7° | F21: / | G21: 40±5° | H21: Polarity Angle | I21: Not CTQ | J21: 40±5° | K21: Three-dimensional coil tester | L21: 40±5° | M21: Three-dimensional coil tester | N21: 5pcs/4h
B22: Function | C22: / | D22: / | E22: / | F22: / | G22: The outline of the image displayed on the magnetic film is clearly visible | H22: Magnetic film | I22: Critical to FATP | J22: The outline of the image displayed on the magnetic film is clearly visible | K22: 磁极片 Magnetic film | L22: The outline of the image displayed on the magnetic film is clearly visible | M22: 磁极片 Magnetic film | N22: NPI Production:100% inspection
B23: Function | C23: / | D23: / | E23: / | F23: / | G23: Polarity Check | H23: Polarity | I23: Critical to FATP | J23: Polarity Check | K23: 极性笔 Polar Pen | L23: Polarity Check | M23: 极性笔 Polar Pen | N23: NPI Production:100% inspection
A24: Assembling | B24: Dim | C24: A | D24: 1 | E24: 4.30±0.10 mm | F24: FAI 1/SPC A | G24: 4.30±0.08 mm | H24: 距离 Distance | I24: Critical to FATP | J24: 4.30±0.08 mm | K24: HG | L24: 4.30±0.08 mm | M24: HG | N24: 3pcs/4h
B25: Dim | C25: B | D25: 2 | E25: 6.19±0.10 mm | F25: FAI 2/SPC B | G25: 6.19±0.08 mm | H25: 距离 Distance | I25: Critical to FATP | J25: 6.19±0.08 mm | K25: HG | L25: 6.19±0.08 mm | M25: HG | N25: 3pcs/4h
B26: Dim | C26: C | D26: 3 | E26: 9.83±0.10 mm | F26: FAI 3/SPC C | G26: 9.83±0.08 mm | H26: 距离 Distance | I26: Critical to FATP | J26: 9.83±0.08 mm | K26: HG | L26: 9.83±0.08 mm | M26: HG | N26: 3pcs/4h
B27: Dim | C27: D | D27: 4 | F27: FAI 4/SPC D | G27: max 0.10 | H27: 轮廓度 Profile | I27: Not CTQ | J27: max 0.10 | K27: CMM | L27: max 0.10 | M27: CMM | N27: 3pcs/4h
B28: Dim | C28: E | D28: 5 | F28: FAI 5/SPC E | G28: max 0.12 | H28: 轮廓度 Profile | I28: Not CTQ | J28: max 0.12 | K28: CMM | L28: max 0.12 | M28: CMM | N28: 3pcs/4h
B29: Dim | C29: F | D29: 6 | F29: FAI 6/SPC F | G29: max 0.12 | H29: 轮廓度 Profile | I29: Not CTQ | J29: max 0.12 | K29: CMM | L29: max 0.12 | M29: CMM | N29: 3pcs/4h
B30: Dim | C30: G | D30: 7 | F30: FAI 7/SPC G | G30: max 0.12 | H30: 轮廓度 Profile | I30: Not CTQ | J30: max 0.12 | K30: CMM | L30: max 0.12 | M30: CMM | N30: 3pcs/4h
B31: Dim | C31: H | D31: 8 | F31: FAI 8/SPC H | G31: 4*max 0.04 | H31: 轮廓度 Profile | I31: Not CTQ | J31: 4*max 0.04 | K31: CMM | L31: max 0.04 | M31: CMM | N31: 3pcs/4h
B32: Function | C32: / | D32: / | E32: / | F32: / | G32: The outline of the image displayed on the magnetic film is clearly visible | H32: Magnetic show | I32: Critical to FATP | J32: The outline of the image displayed on the magnetic film is clearly visible | K32: 磁极片 Magnetic film | L32: The outline of the image displayed on the magnetic film is clearly visible | M32: 磁极片 Magnetic film | N32: 50pcs/2h
B33: Function | C33: / | D33: / | F33: / | H33: 极性测试 Polarity test | I33: Critical to FATP | K33: 极性笔 Magnetic Pen | M33: 极性测试 Polarity test | N33: 50pcs/2h
B34: ORT | C34: / | D34: 9 | E34: OQC ≥32 | F34: / | G34: ≥34 | H34: 达因笔测试 Dyne test | I34: Not CTQ | J34: ≥34 | K34: 达因笔 Dyne pen | L34: ≥34 | M34: 达因笔测试 Dyne test | N34: 5pcs/4h
B35: ORT | C35: / | D35: 10 | E35: Shear force | F35: FAI 10 | G35: R1/L1 ≥200N R2/L2 ≥300N R3/L3 ≥200N R4/L4 ≥100N | H35: Shear force | I35: Critical to FATP | J35: R1/L1 ≥200N R2/L2 ≥200N R3/L3 ≥200N R4/L4 ≥100N | K35: 万能试验机 Universal Tester | L35: R1/L1 ≥200N R2/L2 ≥200N R3/L3 ≥200N R4/L4 ≥100N | M35: 万能试验机 Universal Tester | N35: 5pcs/4h
B36: Function | C36: / | D36: 11 | E36: 1.045±0.07N | F36: FAI 11 | G36: 1.045±0.07N | H36: Retention force | I36: Critical to FATP | J36: 1.045±0.05 N | K36: 万能试验机 Universal Tester | L36: 1.045±0.05 N | M36: 万能试验机 Universal Tester | N36: 5pcs/4h
A37: 100% inspection | B37: Function | C37: / | D37: / | E37: / | F37: / | G37: The outline of the image displayed on the magnetic film is clearly visible | H37: 磁极片 Magnetic film | I37: Critical to FATP | J37: The outline of the image displayed on the magnetic film is clearly visible | K37: 磁极片 Magnetic film | L37: The outline of the image displayed on the magnetic film is clearly visible | M37: 磁极片 Magnetic film | N37: Production:100% inspection
B38: Function | C38: / | D38: / | F38: / | H38: 极性测试 Polarity test | I38: Critical to FATP | K38: 极性笔 Magnetic Pen | M38: 极性测试 Polarity test | N38: AIM:100% inspection
B39: Dim | C39: A | D39: 1 | E39: 4.30±0.10 mm | F39: FAI 1/SPC A | G39: 4.30±0.09 mm | H39: 距离 Distance | I39: Critical to FATP | J39: 4.30±0.09 mm | K39: 通止规 Go/No-go Guage | L39: 4.30±0.09 mm | M39: 通止规 Go/No-go Guage | N39: Production:100% inspection
B40: Dim | C40: B | D40: 2 | E40: 6.19±0.10 mm | F40: FAI 2/SPC B | G40: 6.19±0.09 mm | H40: 距离 Distance | I40: Critical to FATP | J40: 6.19±0.09 mm | K40: 通止规 Go/No-go Guage | L40: 6.19±0.09 mm | M40: 通止规 Go/No-go Guage | N40: Production:100% inspection
B41: Dim | C41: C | D41: 3 | E41: 9.83±0.10 mm | F41: FAI 3/SPC C | G41: 9.83±0.09 mm | H41: 距离 Distance | I41: Critical to FATP | J41: 9.83±0.09 mm | K41: 通止规 Go/No-go Guage | L41: 9.83±0.09 mm | M41: 通止规 Go/No-go Guage | N41: Production:100% inspection
...

Sheet OQC
A1: Project | B1: Build
A2: =Revision!A4 -> B747 BUD | B2: =Revision!B4 -> Ramp
A3: APN | B3: Description
A4: =Revision!A10 -> 613-35102-B(Mirror 613-35106-B) | B4: =Revision!B10 -> OQC
A6: Part Name | B6: APN | C6: Revision | D6: Category Dim, Cos, Function, ORT | E6: Description Detailed inspection items | F6: Control Plan Refer "IQC Reaction Plan"
F7: Inspection Equipment | G7: Sampling Plan | H7: Acceptance Criteria
A8: SUB-ASSY,MAGNET,BUD RET,R,B747 SUB-ASSY,MAGNET,BUD RET,L,B747 | B8: 613-35102-B (Mirror 613-35106-B) | C8: 6 | D8: Dim | E8: Distance 4.30±0.10 mm | F8: HG | G8: 32pcs/Lot | H8: CPK≥1.33
C9: 6 | D9: Dim | E9: Distance 6.19±0.10 mm | F9: HG | G9: 32pcs/Lot | H9: CPK≥1.33
C10: 6 | D10: Dim | E10: Distance 9.83±0.10 mm | F10: HG | G10: 32pcs/Lot | H10: CPK≥1.33
C11: 6 | D11: Dim | E11: Profile for Magnet 1 max 0.10 | F11: CMM | G11: 32pcs/Lot | H11: CPK≥1.33
C12: 6 | D12: Dim | E12: Profile for Magnet 2 max 0.15 | F12: CMM | G12: 32pcs/Lot | H12: CPK≥1.33
C13: 6 | D13: Dim | E13: Profile for Magnet 3 max 0.15 | F13: CMM | G13: 32pcs/Lot | H13: CPK≥1.33
C14: 6 | D14: Dim | E14: Profile for Magnet 4 max 0.15 | F14: CMM | G14: 32pcs/Lot | H14: CPK≥1.33
C15: 6 | D15: Dim | E15: Profile for Magnet 4*Max 0.05 | F15: CMM | G15: 32pcs/Lot | H15: CPK≥1.33
C16: 6 | D16: Function | E16: The outline of the image displayed on the magnetic film is clearly visible | F16: magnetic film | G16: 32pcs/Lot | H16: 0收1退(Ac=0)
C17: 6 | D17: Function | F17: 极性笔 Magnetic Pen | G17: 32pcs/Lot | H17: 0收1退(Ac=0)
C18: 6 | D18: Function | E18: Retention force 1.045±0.07N | F18: 万能试验机+吸力治具 Universal Tester + AF Fixture | G18: NPI 32pcs/Lot MP 10pcs/Lot | H18: 0收1退(Ac=0)
C19: 6 | D19: ORT | E19: Shear force R1/L1 ≥200N R2/L2 ≥300N R3/L3 ≥200N R4/L4 ≥100N | F19: 万能试验机+剪切力治具 Universal Tester+Shear force Fixture | G19: NPI 32pcs/Lot MP 10pcs/Lot | H19: 0收1退(Ac=0)
C20: 6 | D20: ORT | E20: Dyne test OQC ≥32# | F20: 达因笔 Dyne pen | G20: 9pcs/Lot | H20: 0收1退(Ac=0)
C21: 6 | D21: Cos | E21: 069-1770.Class C | F21: Visual | G21: GB2828 AQL 0.4 level 2 | H21: GB2828 AQL 0.4 level 2

Sheet Rel
A1: Project | B1: Build
A2: =IF(Revision!A4="","",Revision!A4) -> B747 BUD | B2: =IF(Revision!B4="","",Revision!B4) -> Ramp
A3: APN | B3: Description
A4: =Revision!A11 -> 160-05811-B(Mirror 160-05815-B) 160-05812-B(Mirror 160-05816-B) 160-05813-B(Mirror 160-05817-B) 160-05814-B(Mirror 160-05816-B) 806-55638-A(Mirror 806-55645-A) 613-35102-B(Mirror 613-35106-B) | B4: =Revision!B11 -> Rel
A6: Rel Requirement | G6: Sample Size / Frequency
A7: Rel title | B7: Rel document | C7: Rel revision date | D7: Rel options | E7: Applicability | F7: Failure criteria | G7: NPI | H7: MP | I7: Re-test Qty*
A8: PP Magnet-SST | B8: ASTM B117-11 | D8: 5%NaCl,35±2°C，PH6.5-7.2, 24hrs | E8: Plating | F8: No corrosion and pitting | G8: 32pcs/Lot | H8: 9pcs/Lot | I8: 32pcs/Lot
A9: PP Magnet-Heat Quench Test | B9: Apple ERS 080-02981-B | D9: 250°C,1h | E9: Plating | F9: No break, crack, peel off, bubble | G9: 9pcs/Lot | H9: 9pcs/Lot | I9: 32pcs/Lot
A10: PP Magnet-HS | D10: 72h 85℃/85% RH 72HR HS | E10: Plating | F10: <5% Decrease in MM | G10: 32pcs/Lot | H10: 10pcs/Lot | I10: 32pcs/Lot
A11: Shunt-SST | B11: ASTM B117-11 | D11: 5%NaCl,35±2°C，PH6.5-7.2, 24hrs | E11: Plating | F11: No corrosion and pitting | G11: 32pcs/Lot | H11: 9pcs/Lot | I11: 32pcs/Lot
A12: ASSY-SST | B12: ASTM B117-11 | D12: 5%NaCl,35±2°C，PH6.5-7.2, 24hrs | E12: Plating | F12: No corrosion and pitting | G12: 10pcs/Lot | H12: 10pcs/Lot | I12: 32pcs/Lot
A13: ASSY-MM Decay After HS | B13: PD environmental rel in Array OQC | D13: 72h 85℃/85% RH 72HR HS | E13: Assembing | F13: <5% Decrease in AF | G13: 9pcs/Lot | H13: / | I13: /
A14: ASSY-AF Decay After HS | B14: PD environmental rel in Array OQC | D14: 72h 85℃/85% RH 72HR HS | E14: Assembing | F14: <5% Decrease in AF | G14: 32pcs/Lot | H14: 3pcs/Lot | I14: 32pcs/Lot

Sheet Instruction
B2: Q-Plan Template Instruction
A3: 1 | B3: File Naming Rule as "Project number_Build name_Part Name_Document type__Vendor name_Date(YYYYMMDD)" (eg. J817_P1_HSG_Q-Plan_McEG_20240701)
A4: 2 | B4: For revison sheet, need add APN for specific process whenever available.
A5: 3 | B5: For CNC prcoess, need add process description (eg. CNC5 structure side finishing CNC).
A6: 4 | B6: For IM process, need add quality control plan for K87 (Ano 0) as well.
A7: 5 | B7: For CTQ category, need split into different categories: Critical to ID feature, Critical to FATP, Critical to HSG assembly, NUD (new/unique/difficult), Not CTQ
A8: 6 | B8: For QC stations (eg. AIM, Ano QC, FQC), need to treat as the same as process station in Q-plan and add its control plan in IPQC.
A9: 7 | B9: For Rel control plan, Rel option stands for specific opition need to be implemented (eg. 504Hrs Heat Soak, 72Hrs Temperature Humidity Cycle, 300hrs Indoor Exposure)
B11: IQC Reaction Plan
B35: Online Quality Control Reaction Plan - Dimension
B60: Online Quality Control Reaction Plan - ORT
B81: Rel Test Reaction Plan
B108: Q-Plan Template Revisions
B109: Revision | C109: Date | D109: Description
B110: 1 | C110: 45443 | D110: Initial release
B111: 2 | C111: 45477 | D111: Changed Q-plan logic, added reaction plan
B112: 3 | C112: 45482 | D112: Small bug fix
B113: 4 | C113: 45509 | D113: Split FAI and IPQC spec, updated reaction plan
B114: 5 | C114: 45513 | D114: Remove "rel" from category
B115: 6 | C115: 45518 | D115: Small bug fix
