Workbook

Sheet Revision
A1: Vendor | B1: Site
A2: Magsound | B2: Ningbo
A3: Project | B3: Build
A4: R240 | B4: DVT
A5: APN | B5: Description
A6: 099-53721-08 | B6: IQC
A7: 099-53721-08 | B7: Machining
A8: 099-53721-08 | B8: Surface Treatment
A9: 099-53721-08 | B9: Assy
A10: 099-53721-08 | B10: OQC
A12: Revision | B12: Date | C12: Revision for | I12: Revision Description | K12: Editor | L12: Approver
C13: IQC | D13: Machining | E13: Surface Treatment | F13: Assy | G13: OQC | H13: HSG Rel
A14: 1 | B14: 46000 | C14: Yes | D14: Yes | E14: Yes | F14: Yes | G14: Yes | H14: Yes | I14: Initial release | K14: Vivian yang
A18: R240 099-51503-01 magnet APN summary
A19: NO. | B19: CATEGORY | C19: APN | D19: Plating | E19: Material | F19: Size-X | G19: Size-Y | H19: Size-Z | I19: MAGNETIZATION ANGLE | J19: Magnetic Moment (DWG spec) | K19: Mganetized | L19: Laser
A20: 1 | B20: MAG,C,FH,HD,TRI,01,TW,THINFPS,R240 | C20: 160-05846 | D20: Bright Zinc | E20: N42SH | F20: 10.17 | G20: 4.55 | H20: 0.9 | I20: 55° OFF Y IN YZ PLANE | J20: 4.65～5.45 | K20: Y | L20: Y
A21: 2 | B21: MAG,C,FH,TRI,01,THINFPS,R240 | C21: 160-05847 | D21: Bright Zinc | E21: N42SH | F21: 5.69 | G21: 5.8 | H21: 0.9 | I21: 55° OFF Y IN YZ PLANE | J21: 3.31～3.89 | K21: Y | L21: Y
A22: 3 | B22: MAG,C,FH,HD,TRI,02,TW,THINFPS,240 | C22: 160-05849 | D22: Bright Zinc | E22: N35SH | F22: 5.96 | G22: 4.55 | H22: 0.9 | I22: 55° OFF Y IN YZ PLANE | J22: 2.49～2.93 | K22: Y | L22: Y
A23: 4 | B23: MAG,C,FH,HD,TRI,03,TW,THINFPS,240 | C23: 160-05851 | D23: Bright Zinc | E23: N35SH | F23: 12.38 | G23: 4.55 | H23: 0.9 | I23: 55° OFF Y IN YZ PLANE | J23: 5.19～6.09 | K23: Y | L23: Y
A24: 5 | B24: MAG,C,FH,TRI,02,THINFPS,R240 | C24: 160-05844 | D24: Bright Zinc | E24: N42SH | F24: 5.18 | G24: 5.8 | H24: 0.9 | I24: 55° OFF Y IN YZ PLANE | J24: 3.02～3.54 | K24: Y | L24: Y
A25: 6 | B25: MAG,C,CH,TRI,01,THINFPS,R240 | C25: 160-05852 | D25: Bright Zinc | E25: N42SH | F25: 4.7 | G25: 5.8 | H25: 0.9 | I25: 55° OFF Y IN YZ PLANE | J25: 2.73～3.21 | K25: Y | L25: Y
A26: 7 | B26: MAG,C,CH,TRI,02,THINFPS,R240 | C26: 160-05850 | D26: Bright Zinc | E26: N42SH | F26: 11.2 | G26: 5.8 | H26: 0.9 | I26: 55° OFF Y IN YZ PLANE | J26: 6.54～7.68 | K26: Y | L26: Y
A27: 8 | B27: MAG,C,CH,HD,TRI,01,TW,THINFPS,R240 | C27: 160-05848 | D27: Bright Zinc | E27: N35SH | F27: 12.56 | G27: 4.55 | H27: 0.9 | I27: 55° OFF Y IN YZ PLANE | J27: 5.26～6.18 | K27: Y | L27: Y(角度+数字镭雕)
A28: 9 | B28: MAG,C,CH,HD,TRI,02,TW,THINFPS,R240 | C28: 160-05845 | D28: Bright Zinc | E28: N35SH | F28: 11.41 | G28: 4.55 | H28: 0.9 | I28: 55° OFF Y IN YZ PLANE | J28: 4.78～5.62 | K28: Y | L28: Y
A29: 10 | B29: MAG,C,ED,01,R413 | C29: 160-05549 | D29: Black Epoxy | E29: 12H | F29: 8.7 | G29: 8.85 | H29: 0.8 | I29: N/A | J29: 3.04～3.57 | K29: N | L29: N
A30: 11 | B30: MAG,C,SLIDER,OPT_1,R413 | C30: 160-05550 | D30: Black Epoxy | E30: 8 | F30: 9 | G30: 20.28 | H30: 0.8 | I30: N/A | J30: 6.46～7.58 | K30: N | L30: N
A31: 13 | B31: MAG,C,ED,02,R413 | C31: 160-05552 | D31: Black Epoxy | E31: 12H | F31: 6.86 | G31: 8.85 | H31: 0.8 | I31: N/A | J31: 2.39～2.80 | K31: N | L31: N
A32: 14 | B32: MAG,C,ED,03,R413 | C32: 160-05553 | D32: Black Epoxy | E32: 12H | F32: 4.06 | G32: 8.85 | H32: 0.8 | I32: N/A | J32: 1.43～1.67 | K32: N | L32: N
A33: 15 | B33: MAG,C,HES,R413 | C33: 160-05554 | D33: Bright Zinc | E33: N35SH | F33: 12 | G33: 10.05 | H33: 0.7 | I33: NORMAL | J33: 8.66～10.17 | K33: N | L33: N
A34: 16 | B34: MAG,C,BAL,R413 | C34: 160-05555 | D34: Bright Zinc | E34: N35SH | F34: 8 | G34: 10 | H34: 0.8 | I34: NORMAL | J34: 6.66～7.82 | K34: N | L34: N
A35: 17 | B35: MAG,C,ED,04,R413 | C35: 160-05556 | D35: Black Epoxy | E35: 12H | F35: 5.46 | G35: 8.85 | H35: 0.8 | I35: N/A | J35: 1.93～2.26 | K35: N | L35: N
A36: 18 | B36: MAG,B,STICK,THINFPS,01,R240 | C36: 160-05842 | D36: Black Epoxy | E36: 12H | F36: 15.58 | G36: 5.8 | H36: 0.7 | I36: N/A | J36: 3.13～3.67 | K36: N | L36: N
A37: 19 | B37: MAG,B,STICK,THINFPS,02,R240 | C37: 160-05843 | D37: Black Epoxy | E37: 12H | F37: 20.79 | G37: 5.8 | H37: 0.7 | I37: N/A | J37: 4.17～4.89 | K37: N | L37: N
A38: 20 | B38: MAG,A,FH,TRI,01,TW,THINFPS,R240 | C38: 160-05861 | D38: Bright Zinc | E38: N45SH | F38: 9.15 | G38: 6.2 | H38: 1.15 | I38: 160°OFF Y IN YZ PLANE | J38: 7.71～9.05 | K38: Y | L38: Y
A39: 21 | B39: MAG,A,FH,TRI,02,THINFPS,R240 | C39: 160-05857 | D39: Bright Zinc | E39: N45SH | F39: 5.69 | G39: 6.2 | H39: 1.15 | I39: 160°OFF Y IN YZ PLANE | J39: 4.78～5.62 | K39: Y | L39: Y(角度+数字镭雕)
A40: 22 | B40: MAG,A,FH,TRI,03,TW,THINFPS,R240 | C40: 160-05858 | D40: Bright Zinc | E40: N45SH | F40: 5.95 | G40: 6.2 | H40: 1.15 | I40: 160°OFF Y IN YZ PLANE | J40: 5.00～5.88 | K40: Y | L40: Y
A41: 23 | B41: MAG,A,FH,TRI,04,TW,THINFPS,R240 | C41: 160-05859 | D41: Bright Zinc | E41: N45SH | F41: 12.38 | G41: 6.2 | H41: 1.15 | I41: 160°OFF Y IN YZ PLANE | J41: 10.45～12.27 | K41: Y | L41: Y
A42: 24 | B42: MAG,A,FH,TRI,05,THINFPS,R240 | C42: 160-05860 | D42: Bright Zinc | E42: N45SH | F42: 5.18 | G42: 6.2 | H42: 1.15 | I42: 160°OFF Y IN YZ PLANE | J42: 4.35～5.11 | K42: Y | L42: Y
... A51: 33 | B51: MAG,A,STICK,02,R240 | C51: 160-05744 | D51: Black Epoxy | E51: 12H | F51: 9.35 | G51: 5.5 | H51: 1.1 | I51: N/A | J51: 2.93~3.43 | K51: N | L51: N
A52: 34 | B52: MAG,BACK,RAIL,01,R240 | C52: 160-06672 | D52: Black Epoxy | E52: 8 | F52: 9 | G52: 10.15 | H52: 0.8 | I52: N/A | J52: 2.95～3.423 | K52: N | L52: N
...

Sheet IQC
A1: Project | B1: Build
A2: =IF(Revision!A4="","",Revision!A4) -> R240 | B2: =IF(Revision!B4="","",Revision!B4) -> DVT
A3: APN | B3: Description
A4: =IF(Revision!A6="","",Revision!A6) -> 099-53721-08 | B4: =IF(Revision!B6="","",Revision!B6) -> IQC
A6: Part Name | B6: APN | C6: Revision | D6: Category Dim, Cos, Function, ORT, Rel | E6: Description Detailed inspection items | F6: Control Plan Refer "IQC Reaction Plan"
F7: Inspection Equipment | G7: Sampling Plan | H7: Acceptance Criteria
A8: Refer to R240 magnet APN summary | B8: Refer table Material info | C8: 1 | D8: Function | E8: Material N35SH-100R2(REE) Br:11.7~12.2KGs Hcj:20 KOe minimum BHmax: 33~36 MGOe | F8: Magnetic permanent testing machine 磁性能测试仪 | G8: 3pcs/Furnace炉 | H8: 0收1退(Ac=0)
A9: Refer to R240 magnet APN summary | B9: Refer table Material info | C9: 1 | D9: Function | E9: Material N42SH-100R2(REE) Br:12.8~13.2KGs Hcj:20 KOe minimum BHmax: 40~43 MGOe | F9: Magnetic permanent testing machine 磁性能测试仪 | G9: 3pcs/Furnace炉 | H9: 0收1退(Ac=0)
A10: Refer to R240 magnet APN summary | B10: Refer table Material info | C10: 1 | D10: Function | E10: Material N45SH-100R2(REE) Br:13.2~13.8KGs Hcj:20 KOe minimum BHmax: 42.98~45.99 MGOe | F10: Magnetic permanent testing machine 磁性能测试仪 | G10: 3pcs/Furnace炉 | H10: 0收1退(Ac=0)
A11: Refer to R240 magnet APN summary | B11: Refer table Material info | C11: 1 | D11: Function | E11: Material 8 Br:6.0~6.8 KGs Hcb:4.5~5.5 KOe Hcj:8.00~10.00 KOe BHmax:7.5~9.0 MGOe | F11: Magnetic permanent testing machine 磁性能测试仪 | G11: 3pcs/Lot | H11: 0收1退(Ac=0)
A12: Refer to R240 magnet APN summary | B12: Refer table Material info | C12: 1 | D12: Function | E12: Material 12H Br:7.2~8.0 KGs Hcb:5.5~6.5 KGs Hcj:9.0~10.0 Koe BHmax:11.0~12.0 MGOe | F12: Magnetic permanent testing machine 磁性能测试仪 | G12: 3pcs/Lot | H12: 0收1退(Ac=0)

Sheet Machining
A1: Project | B1: Build
A2: =IF(Revision!A4="","",Revision!A4) -> R240 | B2: =IF(Revision!B4="","",Revision!B4) -> DVT
A3: APN | B3: Description
A4: =IF(Revision!A7="","",Revision!A7) -> 099-53721-08 | B4: =IF(Revision!B7="","",Revision!B7) -> Machining
A6: Station Station No. with Description | B6: Category Dim, Cos, Function, ORT | C6: Apple DWG Apple official drawing for reference, DO NOT release for online control | F6: Internal DWG Vendor internal drawing been used for by station inspections | J6: FAI Control Plan Refer "Online Quality Control Reaction Plan" | L6: IPQC Control Plan Refer "Online Quality Control Reaction Plan"
C7: SPC No. | D7: FAI No. | E7: Spec | F7: Dim No. | G7: Spec | H7: Description | I7: CTQ Category | J7: FAI Spec | K7: Inspection Equipment | L7: IPQC Spec | M7: Inspection Equipment | N7: Inspection Frequency
A8: 线锯-1 Wire Saw-1 | B8: Dim | C8: - | D8: - | E8: - | F8: FAI 1 | G8: Refer to Sintered Summary Table X ±0.04 | H8: Length | I8: Not CTQ | J8: Refer to Sintered Summary Table X ±0.04 | K8: OMM | L8: Refer to Sintered Summary Table X ±0.03 | M8: OMM | N8: 5pcs/2H
A9: 双面磨-1 Double Side Grinding-1 | B9: Dim | C9: - | D9: - | E9: - | F9: FAI 1 | G9: Refer to Sintered Summary Table X ±0.02 | H9: Length | I9: Not CTQ | J9: Refer to Sintered Summary Table X ±0.02 | K9: OMM | L9: Refer to Sintered Summary Table X ±0.015 | M9: OMM | N9: 5pcs/2H
A10: 线锯-2 Wire Saw-2 | B10: Dim | C10: - | D10: - | E10: - | F10: FAI 2 | G10: Refer to Sintered Summary Table Y ±0.04 | H10: Width | I10: Not CTQ | J10: Refer to Sintered Summary Table Y ±0.04 | K10: OMM | L10: Refer to Sintered Summary Table Y ±0.03 | M10: OMM | N10: 5pcs/2H
A11: 双面磨-2 Double Side Grinding-2 | B11: Dim | C11: - | D11: - | E11: - | F11: FAI 2 | G11: Refer to Sintered Summary Table Y±0.02 | H11: Width | I11: Not CTQ | J11: Refer to Sintered Summary Table Y±0.02 | K11: OMM | L11: Refer to Sintered Summary Table Y±0.015 | M11: OMM | N11: 5pcs/2H
A12: 线锯-3 Wire Saw-3 | B12: Dim | C12: - | D12: - | E12: - | F12: FAI 3 | G12: Refer to Sintered Summary Table Z ±0.04 | H12: Thickness | I12: Not CTQ | J12: Refer to Sintered Summary Table Z ±0.04 | K12: MIC | L12: Refer to Sintered Summary Table Z ±0.03 | M12: MIC | N12: 5pcs/2H
A13: 双面磨-3 Double Side Grinding-3 | B13: Dim | C13: - | D13: - | E13: - | F13: FAI 3 | G13: Refer to Sintered Summary Table Z ±0.02 | H13: Thickness | I13: Not CTQ | J13: Refer to Sintered Summary Table Z ±0.02 | K13: MIC | L13: Refer to Sintered Summary Table Z ±0.015 | M13: MIC | N13: 5pcs/2H
A14: 压铸成型 Compression molding | B14: Dim | C14: - | D14: - | E14: - | F14: FAI 1 | G14: Refer to Bonded Summary Table X ±0.03 | H14: Length | I14: Not CTQ | J14: Refer to Bonded Summary Table X ±0.03 | K14: OMM | L14: Refer to Bonded Summary Table X ±0.023 | M14: OMM | N14: 32pcs/Lot
A15: 压铸成型 Compression molding | B15: Dim | C15: - | D15: - | E15: - | F15: FAI 2 | G15: Refer to Bonded Summary Table Y ±0.03 | H15: Width | I15: Not CTQ | J15: Refer to Bonded Summary Table Y ±0.03 | K15: OMM | L15: Refer to Bonded Summary Table Y ±0.023 | M15: OMM | N15: 32pcs/Lot
A16: 压铸成型 Compression molding | B16: Dim | C16: - | D16: - | E16: - | F16: FAI 3 | G16: Refer to Bonded Summary Table Z ±0.03 | H16: Thickness | I16: Not CTQ | J16: Refer to Bonded Summary Table Z ±0.03 | K16: MIC | L16: Refer to Bonded Summary Table Z ±0.023 | M16: MIC | N16: 32pcs/Lot
A17: 压铸成型 Compression molding | B17: Dim | C17: - | D17: - | E17: - | F17: - | G17: 5.975±0.125 | H17: Density | I17: Not CTQ | J17: 5.975±0.125 | K17: Other | L17: 5.975±0.094 | M17: MIC | N17: 32pcs/Lot
A19: Sintered Summary | F19: Bonded Summary
A20: APNs | B20: X | C20: Y | D20: Z | F20: APNs | G20: X | H20: Y | I20: Z | J20: Density
A21: 160-05846 | B21: 10.17 | C21: 4.55 | D21: 0.9 | F21: 160-05549 | G21: 8.7 | H21: 8.85 | I21: 0.8 | J21: 5.975±0.125
A22: 160-05847 | B22: 5.69 | C22: 5.8 | D22: 0.9 | F22: 160-05550 | G22: 9 | H22: 20.28 | I22: 0.8 | J22: 5.975±0.125
A23: 160-05849 | B23: 5.96 | C23: 4.55 | D23: 0.9 | F23: 160-05552 | G23: 6.86 | H23: 8.85 | I23: 0.8 | J23: 5.975±0.125
A24: 160-05851 | B24: 12.38 | C24: 4.55 | D24: 0.9 | F24: 160-05553 | G24: 4.06 | H24: 8.85 | I24: 0.8 | J24: 5.975±0.125
A25: 160-05844 | B25: 5.18 | C25: 5.8 | D25: 0.9 | F25: 160-05556 | G25: 5.46 | H25: 8.85 | I25: 0.8 | J25: 5.975±0.125
A26: 160-05852 | B26: 4.7 | C26: 5.8 | D26: 0.9 | F26: 160-05842 | G26: 15.58 | H26: 5.8 | I26: 0.7 | J26: 5.975±0.125
A27: 160-05850 | B27: 11.2 | C27: 5.8 | D27: 0.9 | F27: 160-05843 | G27: 20.79 | H27: 5.8 | I27: 0.7 | J27: 5.975±0.125
A28: 160-05848 | B28: 12.56 | C28: 4.55 | D28: 0.9 | F28: 160-05571 | G28: 12 | H28: 11 | I28: 0.8 | J28: 5.975±0.125
A29: 160-05845 | B29: 11.41 | C29: 4.55 | D29: 0.9 | F29: 160-05748 | G29: 3.5 | H29: 12.85 | I29: 1.1 | J29: 5.975±0.125
A30: 160-05554 | B30: 12 | C30: 10.05 | D30: 0.7 | F30: 160-05744 | G30: 9.35 | H30: 5.5 | I30: 1.1 | J30: 5.975±0.125
A31: 160-05555 | B31: 8 | C31: 10 | D31: 0.8 | F31: 160-06672 | G31: 9 | H31: 10.15 | I31: 0.8 | J31: 5.975±0.125
A32: 160-05861 | B32: 9.15 | C32: 6.2 | D32: 1.15 | F32: 160-06671 | G32: 9 | H32: 18.28 | I32: 0.8 | J32: 5.975±0.125
... A34: 160-05858 | B34: 5.95 | C34: 6.2 | D34: 1.15 | F34: 160-05756 | G34: 9.35 | H34: 5.5 | I34: 0.8 | J34: 5.975±0.125
A35: 160-05859 | B35: 12.38 | C35: 6.2 | D35: 1.15
A36: 160-05860 | B36: 5.18 | C36: 6.2 | D36: 1.15
A37: 160-05855 | B37: 4.7 | C37: 6.2 | D37: 1.15
A38: 160-05856 | B38: 11.2 | C38: 6.2 | D38: 1.15
A39: 160-05853 | B39: 12.56 | C39: 6.2 | D39: 1.15
A40: 160-05854 | B40: 11.41 | C40: 3.67 | D40: 1.15
A41: 160-05841 | B41: 11.85 | C41: 3.8 | D41: 0.8
A42: 160-05570 | B42: 7 | C42: 4 | D42: 0.8
A43: 160-05583 | B43: 8.7 | C43: 3.5 | D43: 0.8
...

Sheet Surface Treatment
A1: Project | B1: Build
A2: =IF(Revision!A4="","",Revision!A4) -> R240 | B2: =IF(Revision!B4="","",Revision!B4) -> DVT
A3: APN | B3: Description
A4: =Revision!A8 -> 099-53721-08 | B4: =Revision!B8 -> Surface Treatment
A6: Station Station No. with Description | B6: Category Dim, Cos, Function, ORT | C6: Apple DWG Apple official drawing for reference, DO NOT release for online control | F6: Internal DWG Vendor internal drawing been used for by station inspections | J6: FAI Control Plan Refer "Online Quality Control Reaction Plan" | L6: IPQC Control Plan Refer "Online Quality Control Reaction Plan"
C7: SPC No. | D7: FAI No. | E7: Spec | F7: Dim No. | G7: Spec | H7: Description | I7: CTQ Category | J7: FAI Spec | K7: Inspection Equipment | L7: IPQC Spec | M7: Inspection Equipment | N7: Inspection Frequency
A8: 振动研磨 Tumbling | B8: Cos | C8: - | D8: - | E8: - | F8: / | G8: 0.12mm≤R ≤0.3mm | H8: 倒角度 Corner radius | I8: Not CTQ | J8: 0.12mm≤R ≤0.3mm | K8: 投影仪 Profile Projector | L8: 0.12mm≤R ≤0.3mm | M8: 投影仪 Profile Projector | N8: 5pcs/Barrel
A9: Zn电镀 Zn Plating | B9: Dim | C9: - | D9: - | E9: - | F9: / | G9: Total 6-14μm | H9: 总镀层厚度 Overall Plating Thickness | I9: Not CTQ | J9: Total 6-14μm | K9: XRF镀层测厚仪 XRF Coating Tester | L9: Total 6-14μm | M9: XRF镀层测厚仪 XRF Coating Tester | N9: 9pcs/Barrel
B10: Dim | C10: - | D10: - | E10: - | F10: / | G10: Size, number and crack locations | H10: 开裂分层检查 Crack performance | I10: Not CTQ | J10: Size, number and crack locations | K10: 切片+金相 Section+Optical Microscope | L10: Size, number and crack locations | M10: 切片+金相 Section+Optical Microscope | N10: 9pcs/Barrel
B11: Dim | C11: - | D11: - | E11: - | F11: / | G11: 80-200 GU | H11: 光泽 Gloss | I11: Not CTQ | J11: 80-200 GU | K11: 光泽度计 Gloss Meter | L11: 80-200 GU | M11: 光泽度计 Gloss Meter | N11: 9pcs/Barrel
B12: Rel | C12: - | D12: - | E12: - | F12: / | G12: No corrosion and pitting 24hrs | H12: 盐雾试验 SST | I12: Not CTQ | J12: No corrosion and pitting 24hrs | K12: 盐雾机 SST Tester | L12: No corrosion and pitting 24hrs | M12: 盐雾机 SST Tester | N12: 9pcs/Barrel
B13: ORT | C13: - | D13: - | E13: - | F13: / | G13: 4B | H13: 百格测试 Cross hatch testing | I13: Not CTQ | J13: 4B | K13: 划格刀 Knife | L13: 4B | M13: 划格刀 Knife | N13: 9pcs/Barrel
B14: ORT | C14: - | D14: - | E14: - | F14: / | G14: ≥34 | H14: 达因 Dyne test | I14: Critical to downstream assembly | J14: ≥34 | K14: 达因笔 Dyne pen | L14: ≥34 | M14: 达因笔 Dyne pen | N14: 9pcs/Barrel
B15: Rel | C15: - | D15: - | E15: - | F15: / | G15: No break, crack, peel off, bubble | H15: 热震测试 Heat Quench Test 150C°,1H | I15: Not CTQ | J15: No break, crack, peel off, bubble | K15: 烘箱 Oven | L15: No break, crack, peel off, bubble | M15: 烘箱 Oven | N15: 9pcs/Barrel
B16: Dim | C16: - | D16: - | E16: - | F16: / | G16: 0.12mm≤R ≤0.3mm | H16: 倒角度 Corner radius | I16: Not CTQ | J16: 0.12mm≤R ≤0.3mm | K16: 投影仪 Profile Projector | L16: 0.12mm≤R ≤0.3mm | M16: 投影仪 Profile Projector | N16: 9pcs/Barrel
A17: 黑色环氧喷涂 Black epoxy coating | B17: Dim | C17: - | D17: - | E17: - | F17: / | G17: Total 10-20μm | H17: 总镀层厚度 Overall Plating Thickness | I17: Not CTQ | J17: Total 10-20μm | K17: 切片+金相 Section+Optical Microscope | L17: Total 10-20μm | M17: 切片+金相 Section+Optical Microscope | N17: 3pcs/Lot
B18: Rel | C18: - | D18: - | E18: - | F18: / | G18: No corrosion and pitting 24hrs | H18: 盐雾试验 SST | I18: Not CTQ | J18: No corrosion and pitting 24hrs | K18: 盐雾机 SST Tester | L18: No corrosion and pitting 24hrs | M18: 盐雾机 SST Tester | N18: 10 pcs/lot
B19: ORT | C19: - | D19: - | E19: - | F19: / | G19: 4B | H19: 百格测试 Cross hatch testing | I19: Not CTQ | J19: 4B | K19: 划格刀 Knife | L19: 4B | M19: 划格刀 Knife | N19: 9pcs/lot
B20: ORT | C20: - | D20: - | E20: - | F20: / | G20: ≥34 | H20: 达因 Dyne test | I20: Critical to downstream assembly | J20: ≥34 | K20: 达因笔 Dyne pen | L20: ≥34 | M20: 达因笔 Dyne pen | N20: 9pcs/lot
B21: Rel | C21: - | D21: - | E21: - | F21: / | G21: No break, crack, peel off, bubble | H21: 热震测试 Heat Quench Test 250C+/-10C°,1H +/-2 degrees C for ice bath | I21: Not CTQ | J21: No break, crack, peel off, bubble | K21: 烘箱 Oven | L21: No break, crack, peel off, bubble | M21: 烘箱 Oven | N21: 9pcs/lot
B22: Dim | C22: - | D22: - | E22: - | F22: / | G22: 0.15mm≤R ≤0.35mm | H22: 倒角度 Corner radius | I22: Not CTQ | J22: 0.15mm≤R ≤0.35mm | K22: 投影仪 Profile Projector | L22: 0.15mm≤R ≤0.35mm | M22: 投影仪 Profile Projector | N22: 9pcs/lot
B23: Cos | C23: - | D23: - | E23: - | F23: / | G23: 099-04896_Class D | H23: 外观 Cosmetic | I23: Not CTQ | J23: 099-04896_Class D | K23: 目视 Visual | L23: 099-04896_Class D | M23: 目视 Visual | N23: GB2828 AQL 0.4 level 2
A24: AOI 100%检验 AOI 100%inspection | B24: Dim | C24: SPC A | D24: FAI 1 | E24: X ±0.05 | F24: =D24&"/"&C24 -> FAI 1/SPC A | G24: X ±0.05 | H24: 厚度 Thickness | I24: Critical to downstream assembly | J24: X ±0.048 | K24: AOI | L24: X ±0.048 | M24: AOI | N24: 1
B25: Dim | C25: SPC B | D25: FAI 2 | E25: Y ±0.05 | F25: =D25&"/"&C25 -> FAI 2/SPC B | G25: Y ±0.05 | H25: 长度 Length | I25: Critical to downstream assembly | J25: Y ±0.048 | K25: AOI | L25: Y ±0.048 | M25: AOI | N25: 1
B26: Dim | C26: SPC C | D26: FAI 3 | E26: Z ±0.04 | F26: =D26&"/"&C26 -> FAI 3/SPC C | G26: Z ±0.04 | H26: 宽度 Width | I26: Critical to downstream assembly | J26: Z ±0.038 | K26: AOI | L26: Z ±0.038 | M26: AOI | N26: 1
B27: Cos | C27: - | D27: - | E27: 099-04896_Class D | F27: / | G27: 099-04896_Class D | H27: 外观 Cosmetic | I27: Not CTQ | J27: 099-04896_Class D | K27: 目视 Visual | L27: 099-04896_Class D | M27: AOI | N27: 1
A28: 染磁100%检验 Residues GS inspection | B28: Function | C28: / | D28: / | E28: / | F28: / | G28: 20GS Max | H28: 染磁 Residues GS | I28: Not CTQ | J28: 20GS Max | K28: 磁极片+Bell 表磁计 Pole piece+Guass meter Bell 5180 | L28: 20GS Max | M28: 磁极片+Bell 表磁计 Pole piece+Guass meter Bell 5180 | N28: 500pcs/4h

Sheet Assy
A1: Project | B1: Build
A2: =IF(Revision!A4="","",Revision!A4) -> R240 | B2: =IF(Revision!B4="","",Revision!B4) -> DVT
A3: APN | B3: Description
A4: =IF(Revision!A10="","",Revision!A10) -> 099-53721-08 | B4: Assy
A6: Station Station No. with Description | B6: Category Dim, Cos, Function, ORT | C6: Apple DWG Apple official drawing for reference, DO NOT release for online control | F6: Internal DWG Vendor internal drawing been used for by station inspections | J6: FAI Control Plan Refer "Online Quality Control Reaction Plan" | L6: IPQC Control Plan Refer "Online Quality Control Reaction Plan"
C7: SPC No. | D7: FAI No. | E7: Spec | F7: Dim No. | G7: Spec | H7: Description | I7: CTQ Category | J7: FAI Spec | K7: Inspection Equipment | L7: IPQC Spec | M7: Inspection Equipment | N7: Inspection Frequency
A8: 烧结磁铁 物料检验 Sintered manget Material inspection | B8: Dim | C8: SPC A | D8: FAI 1 | E8: X ±0.05 Refer summary table | F8: =D8&"/"&C8 -> FAI 1/SPC A | G8: X±0.03 Refer summary table | H8: 厚度 Thickness | I8: Critical to downstream assembly | J8: X±0.03 Refer summary table | K8: OMM | L8: X±0.03 Refer summary table | M8: OMM | N8: 32pcs/Lot
B9: Dim | C9: SPC B | D9: FAI 2 | E9: Y±0.05 Refer summary table | F9: =D9&"/"&C9 -> FAI 2/SPC B | G9: Y±0.03 Refer summary table | H9: 长度 Length | I9: Critical to downstream assembly | J9: Y±0.03 Refer summary table | K9: OMM | L9: Y±0.03 Refer summary table | M9: OMM | N9: 32pcs/Lot
B10: Dim | C10: SPC C | D10: FAI 3 | E10: Z±0.04 Refer summary table | F10: =D10&"/"&C10 -> FAI 3/SPC C | G10: Z±0.03 Refer summary table | H10: 宽度 Width | I10: Critical to downstream assembly | J10: Z±0.03 Refer summary table | K10: MIC | L10: Z±0.03 Refer summary table | M10: MIC | N10: 32pcs/Lot
B11: Function | C11: SPC D | D11: FAI 4 | E11: Nominal Refer summary table | F11: =D11&"/"&C11 -> FAI 4/SPC D | G11: Nominal Refer summary table | H11: 磁矩 Magnet Moment | I11: Critical to downstream assembly | J11: Nominal Refer summary table | K11: 3-Axis Helmhotz coils 三轴霍尔木兹线圈 | L11: Nominal Refer summary table | M11: 3-Axis Helmhotz coils 三轴霍尔木兹线圈 | N11: 32pcs/Lot
B12: Function | C12: SPC E | D12: FAI 5 | E12: Nominal±7˚ Refer summary table | F12: =D12&"/"&C12 -> FAI 5/SPC E | G12: Nominal±5˚ Refer summary table | H12: 磁偏角 Magnetic Direction | I12: Critical to downstream assembly | J12: Nominal±5˚ Refer summary table | K12: 3-Axis Helmhotz coils 三轴霍尔木兹线圈 | L12: Nominal±5˚ Refer summary table | M12: 3-Axis Helmhotz coils 三轴霍尔木兹线圈 | N12: 32pcs/Lot
B13: Dim | C13: - | D13: FAI 6 | E13: 0.20 +0.1/-0.08 | F13: FAI 6 | G13: 0.20 +0.1/-0.08 | H13: 倒角-Plane surface Radius | I13: Critical to downstream assembly | J13: 0.20 +0.1/-0.08 | K13: OMM | L13: 0.20 +0.1/-0.08 | M13: OMM | N13: 32pcs/Lot
B14: Dim | C14: - | D14: FAI 7 | E14: Max 0.20 | F14: FAI 7 | G14: Max 0.20 | H14: 倒角-Sidewall Radius | I14: Critical to downstream assembly | J14: Max 0.2 | K14: OMM | L14: Max 0.2 | M14: OMM | N14: 10pcs/Lot
B15: Rel | C15: - | D15: - | E15: - | F15: / | G15: No corrosion and pitting 24hrs | H15: 盐雾试验 SST | I15: Not CTQ | J15: No corrosion and pitting 24hrs(No Laser mark) No corrosion and pitting 12hrs(Laser mark) | K15: 盐雾机 SST Tester | L15: No corrosion and pitting 24hrs(No Laser mark) No corrosion and pitting 12hrs(Laser mark) | M15: 盐雾机 SST Tester | N15: 9pcs/Lot
B16: ORT | C16: - | D16: - | E16: - | F16: / | G16: 4B | H16: 百格测试 Cross hatch testing | I16: Not CTQ | J16: 4B | K16: 划格刀 Knife | L16: 4B | M16: 划格刀 Knife | N16: 9pcs/Lot
B17: ORT | C17: - | D17: - | E17: - | F17: / | G17: ≥34 | H17: 达因 Dyne test | I17: Critical to downstream assembly | J17: ≥34 | K17: 达因笔 Dyne pen | L17: ≥34 | M17: 达因笔 Dyne pen | N17: 9pcs/Lot
B18: ORT | C18: - | D18: - | E18: - | F18: / | G18: No visible cracks at 500x magnification | H18: 开裂分层检查 Crack Performance | I18: Not CTQ | J18: No visible cracks at 500x magnification | K18: 金相显微镜 Cross-section Microscope(min.500x) | L18: No visible cracks at 500x magnification | M18: 金相显微镜 Cross-section Microscope(min.500x) | N18: 9pcs/Lot
B19: ORT | C19: - | D19: - | E19: - | F19: / | G19: ≥50N | H19: 镀层拉力 Plating Pull Force | I19: Not CTQ | J19: ≥50N | K19: Tema YH-9002 | L19: ≥50N | M19: Tema YH-9002 | N19: 3pcs/Lot
B20: Cos | C20: - | D20: - | E20: 099-04896_Class D | F20: / | G20: 099-04896_Class D | H20: 外观 Cosmetic | I20: Not CTQ | J20: 099-04896_Class D | K20: 目视 Visual | L20: 099-04896_Class D | M20: 目视 Visual | N20: GB2828 AQL 0.4 level 2
B21: Dim | C21: - | D21: - | E21: - | F21: Plating Zn | G21: 80-200GU | H21: 光泽 Gloss | I21: Not CTQ | J21: 80-200GU | K21: 光泽度计 Gloss Meter | L21: 80-200GU | M21: 光泽度计 Gloss Meter | N21: 9pcs/Lot
B22: Rel | C22: - | D22: - | E22: - | F22: Plating Zn | G22: MM Decay<5% | H22: 磁衰测试 MM Decay 65℃，30min, | I22: Not CTQ | J22: MM Decay<5% | K22: 烘箱 Oven | L22: MM Decay<5% | M22: 烘箱 Oven | N22: 9pcs/Lot
B23: Rel | C23: - | D23: - | E23: - | F23: Plating Zn | G23: No break, crack, peel off, bubble | H23: 热震测试 Heat Quench Test 150℃,1H | I23: Not CTQ | J23: No break, crack, peel off, bubble | K23: 烘箱 Oven | L23: No break, crack, peel off, bubble | M23: 烘箱 Oven | N23: 9pcs/Lot
B24: Dim | C24: - | D24: - | E24: - | F24: Plating Zn | G24: Total：6-14 μm | H24: 总镀层厚度 Overall Plating Thickness | I24: Not CTQ | J24: Total：6-14 μm | K24: XRF镀层测厚仪 XRF Coating Tester | L24: Total：6-14 μm | M24: XRF镀层测厚仪 XRF Coating Tester | N24: 9pcs/Lot
A25: 粘接磁铁 物料检验 Bonded manget Material inspection | B25: Dim | C25: SPC A | D25: FAI 1 | E25: X±0.05 Refer summary table | F25: =D25&"/"&C25 -> FAI 1/SPC A | G25: X±0.03 Refer summary table | H25: 厚度 Thickness | I25: Critical to downstream assembly | J25: X±0.03 Refer summary table | K25: OMM | L25: X±0.03 Refer summary table | M25: OMM | N25: 32pcs/Lot
B26: Dim | C26: SPC B | D26: FAI 2 | E26: Y±0.05 Refer summary table | F26: =D26&"/"&C26 -> FAI 2/SPC B | G26: Y±0.03 Refer summary table | H26: 长度 Length | I26: Critical to downstream assembly | J26: Y±0.03 Refer summary table | K26: OMM | L26: Y±0.03 Refer summary table | M26: OMM | N26: 32pcs/Lot
B27: Dim | C27: SPC C | D27: FAI 3 | E27: Z±0.04 Refer summary table | F27: =D27&"/"&C27 -> FAI 3/SPC C | G27: Z±0.03 Refer summary table | H27: 宽度 Width | I27: Critical to downstream assembly | J27: Z±0.03 Refer summary table | K27: MIC | L27: Z±0.03 Refer summary table | M27: MIC | N27: 32pcs/Lot
B28: Function | C28: SPC D | D28: FAI 4 | E28: Nominal Refer summary table | F28: =D28&"/"&C28 -> FAI 4/SPC D | G28: Nominal Refer summary table | H28: 磁矩 Magnet Moment | I28: Critical to downstream assembly | J28: Nominal Refer summary table | K28: 3-Axis Helmhotz coils 三轴霍尔木兹线圈 | L28: Nominal Refer summary table | M28: 3-Axis Helmhotz coils 三轴霍尔木兹线圈 | N28: 32pcs/Lot
B29: Dim | C29: - | D29: FAI 6 | E29: 0.25 ±0.1 | F29: FAI 6 | G29: 0.25 ±0.1 | H29: 倒角-Plane surface Radius | I29: Critical to downstream assembly | J29: 0.25 ±0.1 | K29: OMM | L29: 0.25 ±0.1 | M29: OMM | N29: 32pcs/Lot
B30: Dim | C30: - | D30: FAI 7 | E30: Max 0.20 | F30: FAI 7 | G30: Max 0.20 | H30: 倒角-Sidewall Radius | I30: Critical to downstream assembly | J30: Max 0.2 | K30: OMM | L30: Max 0.2 | M30: OMM | N30: 10pcs/Lot
B31: Rel | C31: - | D31: - | E31: - | F31: / | G31: No corrosion and pitting 24hrs | H31: 盐雾试验 SST | I31: Not CTQ | J31: No corrosion and pitting 24hrs | K31: 盐雾机 SST Tester | L31: No corrosion and pitting 24hrs | M31: 盐雾机 SST Tester | N31: 10pcs/Lot
B32: ORT | C32: - | D32: - | E32: - | F32: / | G32: 4B | H32: 百格测试 Cross hatch testing | I32: Not CTQ | J32: 4B | K32: 划格刀 Knife | L32: 4B | M32: 划格刀 Knife | N32: 10pcs/Lot
B33: ORT | C33: - | D33: - | E33: - | F33: / | G33: ≥34 | H33: 达因 Dyne test | I33: Critical to downstream assembly | J33: ≥34 | K33: 达因笔 Dyne pen | L33: ≥34 | M33: 达因笔 Dyne pen | N33: 10pcs/Lot
B34: Rel | C34: - | D34: - | E34: - | F34: / | G34: No break, crack, peel off, bubble | H34: 热震测试 Heat Quench Test 250℃±10C℃,1H 0℃±2℃ for ice bath | I34: Not CTQ | J34: No break, crack, peel off, bubble | K34: 烘箱 Oven | L34: No break, crack, peel off, bubble | M34: 烘箱 Oven | N34: 10pcs/Lot
B35: Rel | C35: - | D35: - | E35: - | F35: / | G35: MM Decay<5% | H35: 磁衰测试 MM Decay 65℃，30min, | I35: Not CTQ | J35: MM Decay<5% | K35: 烘箱 Oven | L35: MM Decay<5% | M35: 烘箱 Oven | N35: 10pcs/Lot
B36: ORT | C36: - | D36: - | E36: - | G36: Total：10-20 μm | H36: 总镀层厚度-Epoxy Overall Plating Thickness | I36: Not CTQ | J36: Total：10-20 μm | K36: 金相显微镜 Cross-section Microscope(min.500x) | L36: Total：10-20 μm | M36: 金相显微镜 Cross-section Microscope(min.500x) | N36: 3pcs/Lot
B37: Cos | C37: - | D37: - | E37: 099-04896_Class D | F37: / | G37: 099-04896_Class D | H37: 外观 Cosmetic | I37: Not CTQ | J37: 099-04896_Class D | K37: 目视 Visual | L37: 099-04896_Class D | M37: 目视 Visual | N37: GB2828 AQL 0.4 level 2
A38: 充磁 Magnetizing | B38: ORT | C38: / | D38: / | E38: / | F38: / | G38: ≥34 | H38: 达因（充磁前测试） Dyne test | I38: Critical to downstream assembly | L38: ≥34 | M38: 达因笔 Dyne pen | N38: 10pcs/Plating batch
B39: Function | C39: SPC D | D39: FAI 4 | E39: Nominal Refer summary table | F39: FAI 4/SPC D | G39: Nominal Refer summary table | H39: 磁矩 Magnet Moment | I39: Critical to downstream assembly | J39: Nominal Refer summary table | K39: 3-Axis Helmhotz coils 三轴霍尔木兹线圈 | L39: Nominal Refer summary table | M39: 3-Axis Helmhotz coils 三轴霍尔木兹线圈 | N39: 5 pcs/2H Any process/material change/5 pcs
B40: Function | C40: SPC E | D40: FAI 5 | E40: Nominal±7˚ Refer summary table | F40: FAI 5/SPC E | G40: Nominal±5˚ Refer summary table | H40: 磁偏角 Magnetic Direction | I40: Critical to downstream assembly | J40: Nominal±5˚ Refer summary table | K40: 3-Axis Helmhotz coils 三轴霍尔木兹线圈 | L40: Nominal±5˚ Refer summary table | M40: 3-Axis Helmhotz coils 三轴霍尔木兹线圈 | N40: 5 pcs/2H Any process/material change/5 pcs
B41: Function | C41: - | D41: - | E41: - | F41: / | G41: / | H41: 极性 Polarity | I41: Critical to downstream assembly | J41: / | K41: / | L41: 极性参考图纸 Polarity Check Follow Drawing | M41: 极性笔 Polarity Pen | N41: 1
...

Sheet OQC
A1: Project | B1: Build
A2: =IF(Revision!A4="","",Revision!A4) -> R240 | B2: =IF(Revision!B4="","",Revision!B4) -> DVT
A3: APN | B3: Description
A4: =IF(Revision!A10="","",Revision!A10) -> 099-53721-08 | B4: =IF(Revision!B10="","",Revision!B10) -> OQC
A6: Part Name | B6: APN | C6: Revision | D6: Category Dim, Cos, Function, ORT, Rel | E6: Description Detailed inspection items | F6: Control Plan Refer "IQC Reaction Plan"
F7: Inspection Equipment | G7: Sampling Plan | H7: Acceptance Criteria
A8: MAGNET,MAP,THINFPS,EXIT,R240 | B8: =A4 -> 099-53721-08 | C8: 1 | D8: Dim | E8: FAI 1/SPC A X ± 0.05 | F8: OMM | G8: 32pcs/Lot | H8: CPK≥1.33
C9: 1 | D9: Dim | E9: FAI 2/SPC B Y ± 0.05 | F9: OMM | G9: 32pcs/Lot | H9: CPK≥1.33
C10: 1 | D10: Dim | E10: FAI3/SPC C Z ±0.04 | F10: MIC | G10: 32pcs/Lot | H10: CPK≥1.33
C11: 1 | D11: Function | E11: FAI4/SPC D Refer to Table MM | F11: 3-Axis Helmhotz coils 三轴霍尔木兹线圈 | G11: 32pcs/Lot | H11: CPK≥1.33
C12: 1 | D12: Function | E12: FAI5/SPC E Nominal ±7˚ | F12: 3-Axis Helmhotz coils 三轴霍尔木兹线圈 | G12: 32pcs/Lot | H12: Yield>99.5%
C13: 1 | D13: Dim | E13: FAI6 0.25 ±0.1(Bonded) 0.2 +0.1/-0.08(Sintered) | F13: OMM | G13: 32pcs/Lot | H13: No Alert(65%)
C14: 1 | D14: Dim | E14: FAI7 Max 0.20(Bonded&Sintered) | F14: OMM | G14: 10pcs/Lot | H14: No Alert(65%)
C15: 1 | D15: Function | E15: 极性 Polarity | F15: Polarity Pen(Manual) | G15: 32pcs/Lot | H15: 0收1退(Ac=0)
C16: 1 | D16: Function | E16: 磁化饱和度(充磁件) Magnetization saturation | F16: Magnetic film(Manual) | G16: 32pcs/Lot | H16: 0收1退(Ac=0)
C17: 1 | D17: Function | E17: 弱磁(非充磁件) Weak magnetization | F17: Magnetic film(Manual) | G17: 32pcs/Lot | H17: 0收1退(Ac=0)
C18: 1 | D18: Rel | E18: 盐雾试验 No corrosion and pitting 24hrs(No Laser mark) No corrosion and pitting 12hrs(Laser mark) | F18: 盐雾机 SST Tester | G18: 10pcs/Lot | H18: 0收1退(Ac=0)
C19: 1 | D19: Rel | E19: 达因（≥34） Dyne test | F19: 达因笔 Dyne pen | G19: 10pcs/Lot | H19: 0收1退(Ac=0)
C20: 1 | D20: Cos | E20: 外观 Cosmetic | F20: 目视 Visual | G20: GB2828 AQL 0.4 level 2 | H20: 0收1退(Ac=0)
A22: NO. | B22: APN | C22: Size-X | D22: Size-Y | E22: Size-Z | F22: MAGNETIZATION ANGLE | G22: MM
A23: 1 | B23: 160-05846 | C23: 10.17 | D23: 4.55 | E23: 0.9 | F23: 55° OFF Y IN YZ PLANE | G23: 4.65～5.45
A24: 2 | B24: 160-05847 | C24: 5.69 | D24: 5.8 | E24: 0.9 | F24: 55° OFF Y IN YZ PLANE | G24: 3.31～3.89
A25: 3 | B25: 160-05849 | C25: 5.96 | D25: 4.55 | E25: 0.9 | F25: 55° OFF Y IN YZ PLANE | G25: 2.49～2.93
A26: 4 | B26: 160-05851 | C26: 12.38 | D26: 4.55 | E26: 0.9 | F26: 55° OFF Y IN YZ PLANE | G26: 5.19～6.09
A27: 5 | B27: 160-05844 | C27: 5.18 | D27: 5.8 | E27: 0.9 | F27: 55° OFF Y IN YZ PLANE | G27: 3.02～3.54
A28: 6 | B28: 160-05852 | C28: 4.7 | D28: 5.8 | E28: 0.9 | F28: 55° OFF Y IN YZ PLANE | G28: 2.73～3.21
A29: 7 | B29: 160-05850 | C29: 11.2 | D29: 5.8 | E29: 0.9 | F29: 55° OFF Y IN YZ PLANE | G29: 6.54～7.68
A30: 8 | B30: 160-05848 | C30: 12.56 | D30: 4.55 | E30: 0.9 | F30: 55° OFF Y IN YZ PLANE | G30: 5.26～6.18
A31: 9 | B31: 160-05845 | C31: 11.41 | D31: 4.55 | E31: 0.9 | F31: 55° OFF Y IN YZ PLANE | G31: 4.78～5.62
A32: 10 | B32: 160-05549 | C32: 8.7 | D32: 8.85 | E32: 0.8 | F32: N/A | G32: 3.04～3.57
A33: 11 | B33: 160-05550 | C33: 9 | D33: 20.28 | E33: 0.8 | F33: N/A | G33: 6.46～7.58
A34: 13 | B34: 160-05552 | C34: 6.86 | D34: 8.85 | E34: 0.8 | F34: N/A | G34: 2.39～2.80
... A70: 51 | B70: 160-05756 | C70: 9.35 | D70: 5.5 | E70: 0.8 | F70: N/A | G70: 2.09～2.45

Sheet Instruction
B2: Q-Plan Template Instruction
A3: 1 | B3: File Naming Rule as "Project number_Build name_Part Name_Document type__Vendor name_Date(YYYYMMDD)" (eg. J817_P1_HSG_Q-Plan_McEG_20240701)
A4: 2 | B4: For revison sheet, need add APN for specific process whenever available.
A5: 3 | B5: For CNC pR2oess, need add process description (eg. CNC5 structure side finishing CNC).
A6: 4 | B6: For IM process, need add quality control plan for K87 (Ano 0) as well.
A7: 5 | B7: For CTQ category, need split into different categories: Critical to ID feature, Critical to FATP, Critical to HSG assembly, NUD (new/unique/difficult), Not CTQ
A8: 6 | B8: For QC stations (eg. AIM, Ano QC, FQC), need to treat as the same as process station in Q-plan and add its control plan in IPQC.
A9: 7 | B9: For Rel control plan, Rel option stands for specific opition need to be implemented (eg. 504Hrs Heat Soak, 72Hrs Temperature Humidity Cycle, 300hrs Indoor Exposure
B11: IQC Reaction Plan
B35: Online Quality Control Reaction Plan - Dimension
B60: Online Quality Control Reaction Plan - ORT
B81: Rel Test Reaction Plan
B108: Q-Plan Template Revisions
B109: Revision | C109: Date | D109: Description
B110: 1 | C110: 45443 | D110: Initial release
B111: 2 | C111: 45477 | D111: Changed Q-plan logic, added reaction plan
B112: 3 | C112: 45482 | D112: Small bug fix
B113: 4 | C113: 45509 | D113: Split FAI and IPQC spec, updated reaction plan
B114: 5 | C114: 45513 | D114: Remove "rel" from category
